<?xml version="1.0" ?>
<!-- =================================================================================== -->
<!-- |    This document was autogenerated by xacro from /tmp/tmp.rDrDagZ9YM/nextage_description/urdf/nextage.urdf.xacro | -->
<!-- |    EDITING THIS FILE BY HAND IS NOT RECOMMENDED                                 | -->
<!-- =================================================================================== -->
<robot name="nextage" xmlns:body="http://playerstage.sourceforge.net/gazebo/xmlschema/#body" xmlns:controller="http://playerstage.sourceforge.net/gazebo/xmlschema/#controller" xmlns:gazebo="http://playerstage.sourceforge.net/gazebo/xmlschema/#gz" xmlns:geom="http://playerstage.sourceforge.net/gazebo/xmlschema/#geom" xmlns:interface="http://playerstage.sourceforge.net/gazebo/xmlschema/#interface" xmlns:joint="http://playerstage.sourceforge.net/gazebo/xmlschema/#joint" xmlns:model="http://playerstage.sourceforge.net/gazebo/xmlschema/#model" xmlns:physics="http://playerstage.sourceforge.net/gazebo/xmlschema/#physics" xmlns:renderable="http://playerstage.sourceforge.net/gazebo/xmlschema/#renderable" xmlns:rendering="http://playerstage.sourceforge.net/gazebo/xmlschema/#rendering" xmlns:sensor="http://playerstage.sourceforge.net/gazebo/xmlschema/#sensor" xmlns:xi="http://www.w3.org/2001/xinclude">
  <material name="Black">
    <color rgba="0.0 0.0 0.0 1.0"/>
  </material>
  <material name="Blue">
    <color rgba="0.0 0.0 0.8 1.0"/>
  </material>
  <material name="Green">
    <color rgba="0.0 0.8 0.0 1.0"/>
  </material>
  <material name="LightGrey">
    <color rgba="0.6 0.6 0.6 1.0"/>
  </material>
  <material name="Grey">
    <color rgba="0.4 0.4 0.4 1.0"/>
  </material>
  <material name="DarkGrey">
    <color rgba="0.2 0.2 0.2 1.0"/>
  </material>
  <material name="Red">
    <color rgba="0.8 0.0 0.0 1.0"/>
  </material>
  <material name="White">
    <color rgba="1.0 1.0 1.0 1.0"/>
  </material>
  <!-- Immitate two head-mount cameras, each of which are not stereo camera
		by themselves but are made to function as stereo by launch file https://github.com/tork-a/rtmros_nextage/blob/indigo-devel/nextage_ros_bridge/launch/nextage_ueye_stereo.launch 
		Values in Gazebo plugin are originally copied from http://gazebosim.org/tutorials?tut=ros_gzplugins#camera
		and only partially tailored as of May 2017 -->
  <!-- NOTE: The poses of headmount and hand cameras are NOT precisely adjusted to
    the 3D model nor the actual hardware config. These configs
    are meant for a rapid prototyping only. -->
  <joint name="CAMERA_HEAD_L" type="fixed">
    <origin rpy="0 0.25 0" xyz="0.0175 0.0725 0.105"/>
    <parent link="HEAD_JOINT1_Link"/>
    <child link="CAMERA_HEAD_L_Link"/>
  </joint>
  <link name="CAMERA_HEAD_L_Link">
    <visual>
      <origin rpy="0 1.5707963267948966 -0.05" xyz="0.0325 0 0"/>
      <geometry>
        <cylinder length="0.01" radius="0.015"/>
      </geometry>
      <material name="Blue"/>
    </visual>
    <inertial>
      <origin rpy="0 0 0" xyz="0 0 0"/>
      <mass value="1e-6"/>
      <inertia ixx="1e-12" ixy="0.0" ixz="0.0" iyy="1e-12" iyz="0.0" izz="1e-12"/>
    </inertial>
  </link>
  <joint name="CAMERA_HEAD_R" type="fixed">
    <origin rpy="0 0.25 0" xyz="0.0175 -0.0725 0.105"/>
    <parent link="HEAD_JOINT1_Link"/>
    <child link="CAMERA_HEAD_R_Link"/>
  </joint>
  <link name="CAMERA_HEAD_R_Link">
    <visual>
      <origin rpy="0 1.5707963267948966 0.05" xyz="0.0325 0 0"/>
      <geometry>
        <cylinder length="0.01" radius="0.015"/>
      </geometry>
      <material name="Blue"/>
    </visual>
    <inertial>
      <origin rpy="0 0 0" xyz="0 0 0"/>
      <mass value="1e-6"/>
      <inertia ixx="1e-12" ixy="0.0" ixz="0.0" iyy="1e-12" iyz="0.0" izz="1e-12"/>
    </inertial>
  </link>
  <link name="WAIST">
    <visual>
      <origin rpy="0 0 0" xyz="0 0 0"/>
      <geometry>
        <mesh filename="/home/takuma/code/isaaclab_rl_wearglove/assets/nextage_description/urdf/meshes/WAIST_Link_mesh.dae"/>
      </geometry>
    </visual>
    <collision>
      <origin rpy="0 0 0" xyz="0.0 0 0.098"/>
      <geometry>
        <cylinder length="0.376" radius="0.06"/>
      </geometry>
    </collision>
    <inertial>
      <mass value="5"/>
      <origin rpy="0 0 0" xyz="0 0 0.15"/>
      <inertia ixx="0.05416666666666667" ixy="0.0" ixz="0.0" iyy="0.05416666666666667" iyz="0.0" izz="0.03333333333333334"/>
    </inertial>
  </link>
  <link name="CHEST_JOINT0_Link">
    <visual>
      <origin rpy="0 0 0" xyz="0 0 0"/>
      <geometry>
        <mesh filename="/home/takuma/code/isaaclab_rl_wearglove/assets/nextage_description/urdf/meshes/CHEST_JOINT0_Link_mesh.dae"/>
      </geometry>
    </visual>
    <collision>
      <origin rpy="0 0 0" xyz="0 0 0.1575"/>
      <geometry>
        <cylinder length="0.385" radius="0.08"/>
      </geometry>
    </collision>
    <collision>
      <origin rpy="0 0 0" xyz="0.04 0.135 0.0423"/>
      <geometry>
        <cylinder length="0.09" radius="0.05"/>
      </geometry>
    </collision>
    <collision>
      <origin rpy="0 0 0" xyz="0.04 -0.135 0.0423"/>
      <geometry>
        <cylinder length="0.09" radius="0.05"/>
      </geometry>
    </collision>
    <collision>
      <origin rpy="0 0 0" xyz="0 0 0.055"/>
      <geometry>
        <box size="0.23 0.18 0.12"/>
      </geometry>
    </collision>
    <collision>
      <origin rpy="0 0 0" xyz="-0.04 0 0.2325"/>
      <geometry>
        <box size="0.25 0.18 0.245"/>
      </geometry>
    </collision>
    <collision>
      <origin rpy="0 0 0" xyz="-0.1525 0 0.279"/>
      <geometry>
        <box size="0.17 0.29 0.225"/>
      </geometry>
    </collision>
    <collision>
      <origin rpy="0 0 0" xyz="0.03 0 0.315"/>
      <geometry>
        <box size="0.085 0.5 0.0365"/>
      </geometry>
    </collision>
    <inertial>
      <mass value="10.0"/>
      <origin rpy="0 -0 0" xyz="0 0 0.2"/>
      <inertia ixx="0.12708333333333333" ixy="0.0" ixz="0.0" iyy="0.12708333333333333" iyz="0.0" izz="0.10416666666666667"/>
    </inertial>
  </link>
  <link name="HEAD_JOINT0_Link">
    <visual>
      <origin rpy="0 0 0" xyz="0 0 0"/>
      <geometry>
        <mesh filename="/home/takuma/code/isaaclab_rl_wearglove/assets/nextage_description/urdf/meshes/HEAD_JOINT0_Link_mesh.dae"/>
      </geometry>
    </visual>
    <collision>
      <origin rpy="1.57079 0 0" xyz="0 0.01 0.08"/>
      <geometry>
        <cylinder length="0.135" radius="0.035"/>
      </geometry>
    </collision>
    <inertial>
      <mass value="0.317929"/>
      <origin rpy="0 -0 0" xyz="0 0.00547848 0"/>
      <inertia ixx="0.0005298816666666668" ixy="0.0" ixz="0.0" iyy="0.0005298816666666668" iyz="0.0" izz="0.0005298816666666668"/>
    </inertial>
  </link>
  <link name="HEAD_JOINT1_Link">
    <visual>
      <origin rpy="0 0 0" xyz="0 0 0"/>
      <geometry>
        <mesh filename="/home/takuma/code/isaaclab_rl_wearglove/assets/nextage_description/urdf/meshes/HEAD_JOINT1_Link_mesh.dae"/>
      </geometry>
    </visual>
    <collision>
      <origin rpy="0 0.26 0" xyz="-0.05 0 0.12"/>
      <geometry>
        <box size="0.27 0.22 0.115"/>
      </geometry>
    </collision>
    <inertial>
      <mass value="0.4"/>
      <origin rpy="0 0.26 0" xyz="-0.05 0 0.12"/>
      <inertia ixx="0.002054166666666667" ixy="0.0" ixz="0.0" iyy="0.0028708333333333333" iyz="0.0" izz="0.004043333333333334"/>
    </inertial>
  </link>
  <link name="LARM_JOINT0_Link">
    <visual>
      <origin rpy="0 0 0" xyz="0 0 0"/>
      <geometry>
        <mesh filename="/home/takuma/code/isaaclab_rl_wearglove/assets/nextage_description/urdf/meshes/LARM_JOINT0_Link_mesh.dae"/>
      </geometry>
    </visual>
    <collision>
      <origin rpy="0 0 0" xyz="0 0.00775 0.095"/>
      <geometry>
        <box size="0.1 0.0815 0.19"/>
      </geometry>
    </collision>
    <collision>
      <origin rpy="1.57079 0 0" xyz="0 0.0875 0.066"/>
      <geometry>
        <cylinder length="0.175" radius="0.042"/>
      </geometry>
    </collision>
    <collision>
      <origin rpy="-0.7 0 0" xyz="0 0.125 0.145"/>
      <geometry>
        <box size="0.048 0.1 0.035"/>
      </geometry>
    </collision>
    <inertial>
      <mass value="1.32626"/>
      <origin rpy="0 -0 0" xyz="0.0 0.05 0.05"/>
      <inertia ixx="0.00207537" ixy="0.00011276" ixz="8.927e-05" iyy="0.00240295" iyz="-4.57e-05" izz="0.00141912"/>
    </inertial>
  </link>
  <link name="LARM_JOINT1_Link">
    <visual>
      <origin rpy="0 0 0" xyz="0 0 0"/>
      <geometry>
        <mesh filename="/home/takuma/code/isaaclab_rl_wearglove/assets/nextage_description/urdf/meshes/LARM_JOINT1_Link_mesh.dae"/>
      </geometry>
    </visual>
    <collision>
      <origin rpy="0 0.3 0" xyz="-0.043 0.12 -0.13"/>
      <geometry>
        <box size="0.08 0.11 0.28"/>
      </geometry>
    </collision>
    <collision>
      <origin rpy="0 0.45 0" xyz="-0.03 0.0518 -0.236"/>
      <geometry>
        <box size="0.122 0.0338 0.062"/>
      </geometry>
    </collision>
    <inertial>
      <mass value="1.14898"/>
      <origin rpy="0 -0 0" xyz="-0.04 0.1 -0.12"/>
      <inertia ixx="0.0154168" ixy="9.95417e-07" ixz="3.38147e-06" iyy="0.0147117" iyz="0.00213719" izz="0.0012658"/>
    </inertial>
  </link>
  <link name="LARM_JOINT2_Link">
    <visual>
      <origin rpy="0 0 0" xyz="0 0 0"/>
      <geometry>
        <mesh filename="/home/takuma/code/isaaclab_rl_wearglove/assets/nextage_description/urdf/meshes/LARM_JOINT2_Link_mesh.dae"/>
      </geometry>
    </visual>
    <collision>
      <origin rpy="1.57079 0 0" xyz="0 0.025 0"/>
      <geometry>
        <cylinder length="0.11" radius="0.049"/>
      </geometry>
    </collision>
    <collision>
      <origin rpy="0 0 0" xyz="0.0945 0.015 -0.03"/>
      <geometry>
        <box size="0.119 0.125 0.1"/>
      </geometry>
    </collision>
    <collision>
      <origin rpy="0 1.57079 0" xyz="0.17 0 -0.03"/>
      <geometry>
        <cylinder length="0.04" radius="0.047"/>
      </geometry>
    </collision>
    <inertial>
      <mass value="0.577518"/>
      <origin rpy="0 -0 0" xyz="0.1 0.01167107 -0.04"/>
      <inertia ixx="0.00143966" ixy="-3e-07" ixz="1.2e-06" iyy="0.00141763" iyz="-7.596e-05" izz="0.0001972"/>
    </inertial>
  </link>
  <link name="LARM_JOINT3_Link">
    <visual>
      <origin rpy="0 0 0" xyz="0 0 0"/>
      <geometry>
        <mesh filename="/home/takuma/code/isaaclab_rl_wearglove/assets/nextage_description/urdf/meshes/LARM_JOINT3_Link_mesh.dae"/>
      </geometry>
    </visual>
    <collision>
      <origin rpy="1.57079 0 0" xyz="0.1495 -0.003 0"/>
      <geometry>
        <cylinder length="0.12" radius="0.035"/>
      </geometry>
    </collision>
    <collision>
      <origin rpy="0 1.57079 0" xyz="0.075 0.0 0.018"/>
      <geometry>
        <cylinder length="0.15" radius="0.04"/>
      </geometry>
    </collision>
    <collision>
      <origin rpy="0 0 0" xyz="0.0585 0.01 0.0185"/>
      <geometry>
        <box size="0.093 0.112 0.037"/>
      </geometry>
    </collision>
    <inertial>
      <mass value="0.457418"/>
      <origin rpy="0 -0 0" xyz="0.1 -0.00395812 -0.00273"/>
      <inertia ixx="0.00069205" ixy="3e-08" ixz="5.2e-07" iyy="0.00068903" iyz="-1.915e-05" izz="0.00013509"/>
    </inertial>
  </link>
  <link name="LARM_JOINT4_Link">
    <visual>
      <origin rpy="0 0 0" xyz="0 0 0"/>
      <geometry>
        <mesh filename="/home/takuma/code/isaaclab_rl_wearglove/assets/nextage_description/urdf/meshes/LARM_JOINT4_Link_mesh.dae"/>
      </geometry>
    </visual>
    <collision>
      <origin rpy="0 0 0" xyz="0 -0.002 -0.06"/>
      <geometry>
        <box size="0.04 0.118 0.06"/>
      </geometry>
    </collision>
    <collision>
      <origin rpy="0 0 0" xyz="0 0 -0.08"/>
      <geometry>
        <cylinder length="0.08" radius="0.037"/>
      </geometry>
    </collision>
    <inertial>
      <mass value="0.418434"/>
      <origin rpy="0 -0 0" xyz="0.00243131 0.00379733 -0.0577036"/>
      <inertia ixx="0.00052016" ixy="1.69e-06" ixz="7.9e-06" iyy="0.00050569" iyz="-5.377e-05" izz="0.00014004"/>
    </inertial>
  </link>
  <link name="LARM_JOINT5_Link">
    <visual>
      <origin rpy="0 0 0" xyz="0 0 0"/>
      <geometry>
        <mesh filename="/home/takuma/code/isaaclab_rl_wearglove/assets/nextage_description/urdf/meshes/LARM_JOINT5_Link_mesh.dae"/>
      </geometry>
    </visual>
    <collision>
      <origin rpy="0 0 0" xyz="0 0 0.0065"/>
      <geometry>
        <cylinder length="0.013" radius="0.037"/>
      </geometry>
    </collision>
    <inertial>
      <mass value="1.05156"/>
      <origin rpy="0 -0 0" xyz="0.0 0.0 -0.08"/>
      <inertia ixx="0.00194072" ixy="1.1e-07" ixz="-0.00042482" iyy="0.00209392" iyz="1.2e-07" izz="0.00035788"/>
    </inertial>
  </link>
  <link name="RARM_JOINT0_Link">
    <visual>
      <origin rpy="0 0 0" xyz="0 0 0"/>
      <geometry>
        <mesh filename="/home/takuma/code/isaaclab_rl_wearglove/assets/nextage_description/urdf/meshes/RARM_JOINT0_Link_mesh.dae"/>
      </geometry>
    </visual>
    <collision>
      <origin rpy="0 0 0" xyz="0 -0.00775 0.095"/>
      <geometry>
        <box size="0.1 0.0815 0.19"/>
      </geometry>
    </collision>
    <collision>
      <origin rpy="1.57079 0 0" xyz="0 -0.0875 0.066"/>
      <geometry>
        <cylinder length="0.175" radius="0.042"/>
      </geometry>
    </collision>
    <collision>
      <origin rpy="0.7 0 0" xyz="0 -0.125 0.145"/>
      <geometry>
        <box size="0.048 0.1 0.035"/>
      </geometry>
    </collision>
    <inertial>
      <mass value="1.32626"/>
      <origin rpy="0 -0 0" xyz="0.0 -0.05 0.05"/>
      <inertia ixx="0.00207537" ixy="-0.00011276" ixz="8.927e-05" iyy="0.00240295" iyz="4.57e-05" izz="0.00141912"/>
    </inertial>
  </link>
  <link name="RARM_JOINT1_Link">
    <visual>
      <origin rpy="0 0 0" xyz="0 0 0"/>
      <geometry>
        <mesh filename="/home/takuma/code/isaaclab_rl_wearglove/assets/nextage_description/urdf/meshes/RARM_JOINT1_Link_mesh.dae"/>
      </geometry>
    </visual>
    <collision>
      <origin rpy="0 0.3 0" xyz="-0.043 -0.12 -0.13"/>
      <geometry>
        <box size="0.08 0.11 0.28"/>
      </geometry>
    </collision>
    <collision>
      <origin rpy="0 0.45 0" xyz="-0.03 -0.0518 -0.236"/>
      <geometry>
        <box size="0.122 0.0338 0.062"/>
      </geometry>
    </collision>
    <inertial>
      <mass value="1.14898"/>
      <origin rpy="0 -0 0" xyz="-0.04 -0.1 -0.12"/>
      <inertia ixx="0.0154168" ixy="-9.95417e-07" ixz="3.38147e-06" iyy="0.0147117" iyz="-0.00213719" izz="0.0012658"/>
    </inertial>
  </link>
  <link name="RARM_JOINT2_Link">
    <visual>
      <origin rpy="0 0 0" xyz="0 0 0"/>
      <geometry>
        <mesh filename="/home/takuma/code/isaaclab_rl_wearglove/assets/nextage_description/urdf/meshes/RARM_JOINT2_Link_mesh.dae"/>
      </geometry>
    </visual>
    <collision>
      <origin rpy="1.57079 0 0" xyz="0 -0.025 0"/>
      <geometry>
        <cylinder length="0.11" radius="0.049"/>
      </geometry>
    </collision>
    <collision>
      <origin rpy="0 0 0" xyz="0.0945 -0.015 -0.03"/>
      <geometry>
        <box size="0.119 0.125 0.1"/>
      </geometry>
    </collision>
    <collision>
      <origin rpy="0 1.57079 0" xyz="0.17 0 -0.03"/>
      <geometry>
        <cylinder length="0.04" radius="0.047"/>
      </geometry>
    </collision>
    <inertial>
      <mass value="0.577518"/>
      <origin rpy="0 -0 0" xyz="0.1 -0.01167107 -0.04"/>
      <inertia ixx="0.00143966" ixy="3e-07" ixz="1.2e-06" iyy="0.00141763" iyz="7.596e-05" izz="0.0001972"/>
    </inertial>
  </link>
  <link name="RARM_JOINT3_Link">
    <visual>
      <origin rpy="0 0 0" xyz="0 0 0"/>
      <geometry>
        <mesh filename="/home/takuma/code/isaaclab_rl_wearglove/assets/nextage_description/urdf/meshes/RARM_JOINT3_Link_mesh.dae"/>
      </geometry>
    </visual>
    <collision>
      <origin rpy="1.57079 0 0" xyz="0.1495 -0.003 0"/>
      <geometry>
        <cylinder length="0.12" radius="0.035"/>
      </geometry>
    </collision>
    <collision>
      <origin rpy="0 1.57079 0" xyz="0.075 0.0 0.018"/>
      <geometry>
        <cylinder length="0.15" radius="0.04"/>
      </geometry>
    </collision>
    <collision>
      <origin rpy="0 0 0" xyz="0.0585 -0.01 0.0185"/>
      <geometry>
        <box size="0.093 0.112 0.037"/>
      </geometry>
    </collision>
    <inertial>
      <mass value="0.457418"/>
      <origin rpy="0 -0 0" xyz="0.1 0.00395812 -0.00273"/>
      <inertia ixx="0.00069205" ixy="-3e-08" ixz="5.2e-07" iyy="0.00068903" iyz="1.915e-05" izz="0.00013509"/>
    </inertial>
  </link>
  <link name="RARM_JOINT4_Link">
    <visual>
      <origin rpy="0 0 0" xyz="0 0 0"/>
      <geometry>
        <mesh filename="/home/takuma/code/isaaclab_rl_wearglove/assets/nextage_description/urdf/meshes/RARM_JOINT4_Link_mesh.dae"/>
      </geometry>
    </visual>
    <collision>
      <origin rpy="0 0 0" xyz="0 -0.002 -0.06"/>
      <geometry>
        <box size="0.04 0.118 0.06"/>
      </geometry>
    </collision>
    <collision>
      <origin rpy="0 0 0" xyz="0 0 -0.08"/>
      <geometry>
        <cylinder length="0.08" radius="0.037"/>
      </geometry>
    </collision>
    <inertial>
      <mass value="0.418434"/>
      <origin rpy="0 -0 0" xyz="0.00243131 -0.00379733 -0.0577036"/>
      <inertia ixx="0.00052016" ixy="-1.69e-06" ixz="7.9e-06" iyy="0.00050569" iyz="5.377e-05" izz="0.00014004"/>
    </inertial>
  </link>
  <link name="RARM_JOINT5_Link">
    <visual>
      <origin rpy="0 0 0" xyz="0 0 0"/>
      <geometry>
        <mesh filename="/home/takuma/code/isaaclab_rl_wearglove/assets/nextage_description/urdf/meshes/RARM_JOINT5_Link_mesh.dae"/>
      </geometry>
    </visual>
    <collision>
      <origin rpy="0 0 0" xyz="0 0 0.0065"/>
      <geometry>
        <cylinder length="0.013" radius="0.037"/>
      </geometry>
    </collision>
    <inertial>
      <mass value="1.05156"/>
      <origin rpy="0 -0 0" xyz="0.0 0.0 -0.08"/>
      <inertia ixx="0.00194072" ixy="-1.1e-07" ixz="-0.00042482" iyy="0.00209392" iyz="-1.2e-07" izz="0.00035788"/>
    </inertial>
  </link>
  <joint name="CHEST_JOINT0" type="revolute">
    <parent link="WAIST"/>
    <child link="CHEST_JOINT0_Link"/>
    <origin rpy="0 0 0" xyz="0 0 0.267"/>
    <axis xyz="0 0 1"/>
    <limit effort="100" lower="-3.14159" upper="3.14159" velocity="2.513274"/>
    <dynamics damping="0.2" friction="0"/>
  </joint>
  <joint name="HEAD_JOINT0" type="revolute">
    <parent link="CHEST_JOINT0_Link"/>
    <child link="HEAD_JOINT0_Link"/>
    <origin rpy="0 0 0" xyz="0 0 0.302"/>
    <axis xyz="0 0 1"/>
    <limit effort="100" lower="-1.22173" upper="1.22173" velocity="6.684611"/>
  </joint>
  <joint name="HEAD_JOINT1" type="revolute">
    <parent link="HEAD_JOINT0_Link"/>
    <child link="HEAD_JOINT1_Link"/>
    <origin rpy="0 0 0" xyz="0 0 0.08"/>
    <axis xyz="0 1 0"/>
    <limit effort="100" lower="-0.401425" upper="1.308997" velocity="6.684611"/>
  </joint>
  <joint name="LARM_JOINT0" type="revolute">
    <parent link="CHEST_JOINT0_Link"/>
    <child link="LARM_JOINT0_Link"/>
    <origin rpy="0 0 0" xyz="0.04 0.135 0.1015"/>
    <axis xyz="0 0 1"/>
    <limit effort="150" lower="-1.5707963" upper="1.5707963" velocity="3.892084"/>
    <dynamics damping="0.5" friction="0.5"/>
  </joint>
  <joint name="LARM_JOINT1" type="revolute">
    <parent link="LARM_JOINT0_Link"/>
    <child link="LARM_JOINT1_Link"/>
    <origin rpy="0 0 0" xyz="0 0 0.066"/>
    <axis xyz="0 1 0"/>
    <limit effort="150" lower="-2.44346" upper="1.0471975" velocity="2.426008"/>
    <dynamics damping="0.5" friction="0.5"/>
  </joint>
  <joint name="LARM_JOINT2" type="revolute">
    <parent link="LARM_JOINT1_Link"/>
    <child link="LARM_JOINT2_Link"/>
    <origin rpy="0 0 0" xyz="0 0.095 -0.25"/>
    <axis xyz="0 1 0"/>
    <limit effort="150" lower="-1.22173" upper="1.5707963" velocity="3.630285"/>
    <dynamics damping="0.5" friction="0.5"/>
  </joint>
  <joint name="LARM_JOINT3" type="revolute">
    <parent link="LARM_JOINT2_Link"/>
    <child link="LARM_JOINT3_Link"/>
    <origin rpy="0 0 0" xyz="0.1805 0 -0.03"/>
    <axis xyz="1 0 0"/>
    <limit effort="150" lower="-3.1415926" upper="1.7453292" velocity="6.352998"/>
    <dynamics damping="0.5" friction="0.5"/>
  </joint>
  <joint name="LARM_JOINT4" type="revolute">
    <parent link="LARM_JOINT3_Link"/>
    <child link="LARM_JOINT4_Link"/>
    <origin rpy="0 0 0" xyz="0.1495 0 0"/>
    <axis xyz="0 1 0"/>
    <limit effort="150" lower="-3.4" upper="1.134464" velocity="6.352998"/>
    <dynamics damping="0.5" friction="0.5"/>
  </joint>
  <joint name="LARM_JOINT5" type="revolute">
    <parent link="LARM_JOINT4_Link"/>
    <child link="LARM_JOINT5_Link"/>
    <origin rpy="0 0 0" xyz="0 0 -0.1335"/>
    <axis xyz="0 0 1"/>
    <limit effort="150" lower="-2.7123889" upper="2.7123889" velocity="6.352998"/>
    <dynamics damping="0.5" friction="0.5"/>
  </joint>
  <joint name="RARM_JOINT0" type="revolute">
    <parent link="CHEST_JOINT0_Link"/>
    <child link="RARM_JOINT0_Link"/>
    <origin rpy="0 0 0" xyz="0.04 -0.135 0.1015"/>
    <axis xyz="0 0 1"/>
    <limit effort="150" lower="-1.570796" upper="1.570796" velocity="3.892084"/>
    <dynamics damping="0.5" friction="0.5"/>
  </joint>
  <joint name="RARM_JOINT1" type="revolute">
    <parent link="RARM_JOINT0_Link"/>
    <child link="RARM_JOINT1_Link"/>
    <origin rpy="0 0 0" xyz="0 0 0.066"/>
    <axis xyz="0 1 0"/>
    <limit effort="150" lower="-2.44346" upper="1.047197" velocity="2.426008"/>
    <dynamics damping="0.5" friction="0.5"/>
  </joint>
  <joint name="RARM_JOINT2" type="revolute">
    <parent link="RARM_JOINT1_Link"/>
    <child link="RARM_JOINT2_Link"/>
    <origin rpy="0 0 0" xyz="0 -0.095 -0.25"/>
    <axis xyz="0 1 0"/>
    <limit effort="150" lower="-1.22173" upper="1.570796" velocity="3.630285"/>
    <dynamics damping="0.5" friction="0.5"/>
  </joint>
  <joint name="RARM_JOINT3" type="revolute">
    <parent link="RARM_JOINT2_Link"/>
    <child link="RARM_JOINT3_Link"/>
    <origin rpy="0 0 0" xyz="0.1805 0 -0.03"/>
    <axis xyz="1 0 0"/>
    <limit effort="150" lower="-1.74532" upper="3.141592" velocity="6.352998"/>
    <dynamics damping="0.5" friction="0.5"/>
  </joint>
  <joint name="RARM_JOINT4" type="revolute">
    <parent link="RARM_JOINT3_Link"/>
    <child link="RARM_JOINT4_Link"/>
    <origin rpy="0 0 0" xyz="0.1495 0 0"/>
    <axis xyz="0 1 0"/>
    <limit effort="150" lower="-3.4" upper="1.134464" velocity="6.352998"/>
    <dynamics damping="0.5" friction="0.5"/>
  </joint>
  <joint name="RARM_JOINT5" type="revolute">
    <parent link="RARM_JOINT4_Link"/>
    <child link="RARM_JOINT5_Link"/>
    <origin rpy="0 0 0" xyz="0 0 -0.1335"/>
    <axis xyz="0 0 1"/>
    <limit effort="150" lower="-2.712388" upper="2.712388" velocity="6.352998"/>
    <dynamics damping="0.5" friction="0.5"/>
  </joint>
  
  <!-- Work-around for KDL base-link inertia problem; also adheres to ROS standard-->
  <link name="base_link"/>
  <joint name="base_to_dummy" type="fixed">
    <parent link="base_link"/>
    <child link="nextage_base"/>
  </joint>
  <link name="nextage_base">
    <visual>
      <origin rpy="0 0 0" xyz="0 0 0"/>
      <geometry>
        <mesh filename="/home/takuma/code/isaaclab_rl_wearglove/assets/nextage_description/urdf/meshes/BASE_Link_mesh.dae"/>
      </geometry>
    </visual>
    <collision>
      <origin rpy="0 0 0" xyz="-0.19 0 -0.435"/>
      <geometry>
        <box size="0.585 0.585 0.72"/>
      </geometry>
    </collision>
    <collision>
      <origin rpy="0 0 0" xyz="0.0675 0.2575 -0.82"/>
      <geometry>
        <sphere radius="0.03"/>
      </geometry>
    </collision>
    <collision>
      <origin rpy="0 0 0" xyz="0.0675 -0.2575 -0.82"/>
      <geometry>
        <sphere radius="0.03"/>
      </geometry>
    </collision>
    <collision>
      <origin rpy="0 0 0" xyz="-0.4475 0.2575 -0.82"/>
      <geometry>
        <sphere radius="0.03"/>
      </geometry>
    </collision>
    <collision>
      <origin rpy="0 0 0" xyz="-0.4475 -0.2575 -0.82"/>
      <geometry>
        <sphere radius="0.03"/>
      </geometry>
    </collision>
    <inertial>
      <mass value="40"/>
      <origin rpy="0 0 0" xyz="-0.19 0 -0.435"/>
      <inertia ixx="2.86875" ixy="0.0" ixz="0.0" iyy="2.86875" iyz="0.0" izz="2.2815"/>
    </inertial>
  </link>
  <joint name="base_to_waist" type="fixed">
    <parent link="nextage_base"/>
    <child link="WAIST"/>
  </joint>

  <joint name="right_gripper_base_joint" type="fixed">
    <parent link="RARM_JOINT5_Link"/>
    <child link="robotiq_85_base_link_R"/>
    <origin rpy="0 3.1415 1.571" xyz="0 0 0"/>
  </joint>
  
  <joint name="left_gripper_base_joint" type="fixed">
    <parent link="LARM_JOINT5_Link"/>
    <child link="robotiq_85_base_link_L"/>
    <origin rpy="0 3.1415 1.571" xyz="0 0 0"/>
  </joint>

  <!-- L gripper -->
  <link
    name="robotiq_85_base_link_L">
    <inertial>
      <origin
        xyz="0.00021987 -2.3546E-10 0.030163"
        rpy="0 0 0" />
      <mass
        value="0.30915" />
      <inertia
        ixx="0.00028972"
        ixy="-5.7879E-10"
        ixz="-1.8543E-06"
        iyy="0.00030737"
        iyz="1.682E-12"
        izz="0.00019914" />
    </inertial>
    <visual>
      <origin
        xyz="0 0 0"
        rpy="0 0 0" />
      <geometry>
        <mesh
          filename="/home/takuma/code/isaaclab_rl_wearglove/assets/nextage_description/urdf/meshes/robotiq_85_base_link_fine.STL" />
      </geometry>
      <material
        name="">
        <color
          rgba="0.1 0.1 0.1 1" />
      </material>
    </visual>
    <collision>
      <origin
        xyz="0 0 0"
        rpy="0 0 0" />
      <geometry>
        <mesh
          filename="/home/takuma/code/isaaclab_rl_wearglove/assets/nextage_description/urdf/meshes/robotiq_85_base_link_coarse.STL" />
      </geometry>
    </collision>
  </link>
  <link
    name="left_outer_knuckle_L">
    <inertial>
      <origin
        xyz="0.0178331863169983 3.68915177224286E-11 0.0021442477325704"
        rpy="0 0 0" />
      <mass
        value="0.00684838849434396" />
      <inertia
        ixx="2.66832029033166E-07"
        ixy="1.66142314639824E-15"
        ixz="1.45945633322873E-07"
        iyy="1.3889233257419E-06"
        iyz="2.82951161241588E-15"
        izz="1.26603336914415E-06" />
    </inertial>
    <visual>
      <origin
        xyz="0 0 0"
        rpy="0 0 0" />
      <geometry>
        <mesh
          filename="/home/takuma/code/isaaclab_rl_wearglove/assets/nextage_description/urdf/meshes/outer_knuckle_fine.STL" />
      </geometry>
      <material
        name="">
        <color
          rgba="0.1 0.1 0.1 1" />
      </material>
    </visual>
    <collision>
      <origin
        xyz="0 0 0"
        rpy="0 0 0" />
      <geometry>
        <mesh
          filename="/home/takuma/code/isaaclab_rl_wearglove/assets/nextage_description/urdf/meshes/outer_knuckle_coarse.STL" />
      </geometry>
    </collision>
  </link>
  <joint
    name="finger_joint_L"
    type="revolute">
    <origin
      xyz="0.0306011444260539 0 0.0627920162695395"
      rpy="0 0 0" />
    <parent
      link="robotiq_85_base_link_L" />
    <child
      link="left_outer_knuckle_L" />
    <axis
      xyz="0 -1 0" />
    <limit
      lower="0"
      upper="0.725"
      velocity="2.0"
      effort="1000" />
    <!-- default upper was 0.725 -->

  </joint>
  <link
    name="left_outer_finger_L">
    <inertial>
      <origin
        xyz="0.00131451599174296 2.88942057994543E-15 0.0215404163180413"
        rpy="0 0 0" />
      <mass
        value="0.0273093985570947" />
      <inertia
        ixx="8.51629628283022E-06"
        ixy="2.58174336207405E-19"
        ixz="3.83829504344079E-07"
        iyy="6.9133328065108E-06"
        iyz="-7.58589926143789E-19"
        izz="2.25006832221981E-06" />
    </inertial>
    <visual>
      <origin
        xyz="0 0 0"
        rpy="0 0 0" />
      <geometry>
        <mesh
          filename="/home/takuma/code/isaaclab_rl_wearglove/assets/nextage_description/urdf/meshes/outer_finger_fine.STL" />
      </geometry>
      <material
        name="">
        <color
          rgba="0.1 0.1 0.1 1" />
      </material>
    </visual>
    <collision>
      <origin
        xyz="0 0 0"
        rpy="0 0 0" />
      <geometry>
        <mesh
          filename="/home/takuma/code/isaaclab_rl_wearglove/assets/nextage_description/urdf/meshes/outer_finger_coarse.STL" />
      </geometry>
    </collision>
  </link>
  <joint
    name="left_outer_finger_joint_L"
    type="fixed">
    <origin
      xyz="0.0316910442266543 0 -0.00193396375724605"
      rpy="0 0 0" />
    <parent
      link="left_outer_knuckle_L" />
    <child
      link="left_outer_finger_L" />
    <axis
      xyz="0 -1 0" />
  </joint>
  <!-- <link
    name="left_inner_knuckle_L">
    <inertial>
      <origin
        xyz="0.017097546626628 -3.93808524389535E-10 0.0224918438201868"
        rpy="0 0 0" />
      <mass
        value="0.0110930853895903" />
      <inertia
        ixx="4.23392770691541E-06"
        ixy="5.748978936968E-15"
        ixz="1.78855677119788E-06"
        iyy="3.96548790524392E-06"
        iyz="1.05464666369669E-14"
        izz="3.24068002883007E-06" />
    </inertial>
    <visual>
      <origin
        xyz="0 0 0"
        rpy="0 0 0" />
      <geometry>
        <mesh
          filename="/home/takuma/code/isaaclab_rl_wearglove/assets/nextage_description/urdf/meshes/inner_knuckle_fine.STL" />
      </geometry>
      <material
        name="">
        <color
          rgba="0.1 0.1 0.1 1" />
      </material>
    </visual>
    <collision>
      <origin
        xyz="0 0 0"
        rpy="0 0 0" />
      <geometry>
        <mesh
          filename="/home/takuma/code/isaaclab_rl_wearglove/assets/nextage_description/urdf/meshes/inner_knuckle_coarse.STL" />
      </geometry>
    </collision>
  </link>
  <joint
    name="left_inner_knuckle_joint_L"
    type="revolute">
    <origin
      xyz="0.0127000000001501 0 0.0693074999999639"
      rpy="0 0 0" />
    <parent
      link="robotiq_85_base_link_L" />
    <child
      link="left_inner_knuckle_L" />
    <axis
      xyz="0 -1 0" />
    <limit
      lower="0"
      upper="0.8757"
      velocity="2.0"
      effort="1000" />
    <mimic 
      joint="finger_joint_L"
      multiplier="1"
      offset="0" />
  </joint> -->
  <link
    name="left_inner_finger_L">
    <inertial>
      <origin
        xyz="0.0060275613594574 -6.29183141465421E-15 0.00669925693133241"
        rpy="0 0 0" />
      <mass
        value="0.00724255346165745" />
      <inertia
        ixx="1.47824274053603E-06"
        ixy="-3.94884463570303E-19"
        ixz="-3.45268847648622E-07"
        iyy="1.70064480838395E-06"
        iyz="3.5059838910097E-19"
        izz="4.77151336838364E-07" />
    </inertial>
    <visual>
      <origin
        xyz="0 0 0"
        rpy="0 0 0" />
      <geometry>
        <mesh
          filename="/home/takuma/code/isaaclab_rl_wearglove/assets/nextage_description/urdf/meshes/inner_finger_fine.STL" />
      </geometry>
      <material
        name="">
        <color
          rgba="0.1 0.1 0.1 1" />
      </material>
    </visual>
    <collision>
      <origin
        xyz="0 0 0"
        rpy="0 0 0" />
      <geometry>
        <mesh
          filename="/home/takuma/code/isaaclab_rl_wearglove/assets/nextage_description/urdf/meshes/inner_finger_coarse.STL" />
      </geometry>
    </collision>
  </link>
  <joint
    name="left_inner_finger_joint_L"
    type="revolute">
    <!-- <origin
      xyz="0.034585310861294 0 0.0454970193817975"
      rpy="0 0 0" /> -->
    <origin
      xyz="-0.01500688 0 0.05394647"
      rpy="0 0 0" />
    <parent
      link="left_outer_finger_L" />
    <!-- <parent link="left_outer_finger_L"/> -->
    <child
      link="left_inner_finger_L" />
    <axis
      xyz="0 -1 0" />
    <limit
      lower="-0.8757"
      upper="0.0"
      velocity="2.0"
      effort="1000" />
    <mimic 
      joint="finger_joint_L"
      multiplier="-1"
      offset="0" />
  </joint>
  <!-- <link
    name="right_inner_knuckle_L">
    <inertial>
      <origin
        xyz="0.0168606186773776 3.93808471820465E-10 0.0226699950793434"
        rpy="0 0 0" />
      <mass
        value="0.0110930853895903" />
      <inertia
        ixx="4.27134775939882E-06"
        ixy="-8.53568456728898E-15"
        ixz="1.77774229944246E-06"
        iyy="3.96548790524392E-06"
        iyz="-8.45108024914164E-15"
        izz="3.20325997634666E-06" />
    </inertial>
    <visual>
      <origin
        xyz="0 0 0"
        rpy="0 0 0" />
      <geometry>
        <mesh
          filename="/home/takuma/code/isaaclab_rl_wearglove/assets/nextage_description/urdf/meshes/inner_knuckle_fine.STL" />
      </geometry>
      <material
        name="">
        <color
          rgba="0.1 0.1 0.1 1" />
      </material>
    </visual>
    <collision>
      <origin
        xyz="0 0 0"
        rpy="0 0 0" />
      <geometry>
        <mesh
          filename="/home/takuma/code/isaaclab_rl_wearglove/assets/nextage_description/urdf/meshes/inner_knuckle_coarse.STL" />
      </geometry>
    </collision>
  </link>  -->
  <!-- <joint
    name="right_inner_knuckle_joint_L"
    type="revolute">
    <origin
      xyz="-0.0126999999998499 0 0.0693075000000361"
      rpy="0 0 3.14159265358979" />
    <parent
      link="robotiq_85_base_link_L" />
    <child
      link="right_inner_knuckle_L" />
    <axis
      xyz="0 1 0" />
    <limit
      lower="-0.8757"
      upper="0.0"
      velocity="2.0"
      effort="1000" />
    <mimic 
      joint="finger_joint_L"
      multiplier="-1"
      offset="0" />
  </joint> -->
  <link
    name="right_inner_finger_L">
    <inertial>
      <origin
        xyz="0.00602756228812038 -6.47284509480176E-15 0.00669925609578108"
        rpy="0 0 0" />
      <mass
        value="0.00724255346165744" />
      <inertia
        ixx="1.47824283625957E-06"
        ixy="-3.95952064019123E-19"
        ixz="-3.45268708875543E-07"
        iyy="1.70064480838394E-06"
        iyz="3.55286507960029E-19"
        izz="4.77151241114822E-07" />
    </inertial>
    <visual>
      <origin
        xyz="0 0 0"
        rpy="0 0 0" />
      <geometry>
        <mesh
          filename="/home/takuma/code/isaaclab_rl_wearglove/assets/nextage_description/urdf/meshes/inner_finger_fine.STL" />
      </geometry>
      <material
        name="">
        <color
          rgba="0.1 0.1 0.1 1" />
      </material>
    </visual>
    <collision>
      <origin
        xyz="0 0 0"
        rpy="0 0 0" />
      <geometry>
        <mesh
          filename="/home/takuma/code/isaaclab_rl_wearglove/assets/nextage_description/urdf/meshes/inner_finger_coarse.STL" />
      </geometry>
    </collision>
  </link>
  <joint
    name="right_inner_finger_joint_L"
    type="revolute">
    <!-- <origin
      xyz="0.0341060475457406 0 0.0458573878541688"
      rpy="0 0 0" /> -->
    <origin
      xyz="-0.0155046878 0 0.0539742281"
      rpy="0 0 0" />
    <parent
      link="right_outer_finger_L" />
    <child
      link="right_inner_finger_L" />
    <axis
      xyz="0 1 0" />
    <limit
      lower="0"
      upper="0.8757"
      velocity="2.0"
      effort="1000" />
    <mimic 
      joint="finger_joint_L"
      multiplier="1"
      offset="0" />
  </joint>
  <link
    name="right_outer_knuckle_L">
    <inertial>
      <origin
        xyz="0.0178097074051638 3.60493211424024E-11 0.00233123458346721"
        rpy="0 0 0" />
      <mass
        value="0.00684838849401352" />
      <inertia
        ixx="2.70004361573169E-07"
        ixy="1.59579467624491E-15"
        ixz="1.56396493788199E-07"
        iyy="1.38892332558312E-06"
        iyz="2.82357800318817E-15"
        izz="1.26286103637978E-06" />
    </inertial>
    <visual>
      <origin
        xyz="0 0 0"
        rpy="0 0 0" />
      <geometry>
        <mesh
          filename="/home/takuma/code/isaaclab_rl_wearglove/assets/nextage_description/urdf/meshes/outer_knuckle_fine.STL" />
      </geometry>
      <material
        name="">
        <color
          rgba="0.1 0.1 0.1 1" />
      </material>
    </visual>
    <collision>
      <origin
        xyz="0 0 0"
        rpy="0 0 0" />
      <geometry>
        <mesh
          filename="/home/takuma/code/isaaclab_rl_wearglove/assets/nextage_description/urdf/meshes/outer_knuckle_coarse.STL" />
      </geometry>
    </collision>
  </link>
  <joint
    name="right_outer_knuckle_joint_L"
    type="revolute">
    <origin
      xyz="-0.0306011444258893 0 0.0627920162695395"
      rpy="0 0 3.14159265358979" />
    <parent
      link="robotiq_85_base_link_L" />
    <child
      link="right_outer_knuckle_L" />
    <axis
      xyz="0 1 0" />
    <!-- <limit
      lower="0"
      upper="0.8757"
      velocity="2.0"
      effort="1000" /> -->
    <limit
      lower="-0.8757"
      upper="0.0"
      velocity="2.0"
      effort="1000" />
    <mimic 
      joint="finger_joint_L"
      multiplier="-1"
      offset="0" />
  </joint>
  <link
    name="right_outer_finger_L">
    <inertial>
      <origin
        xyz="0.00108844269639009 -2.611488350845E-15 0.0215530225245502"
        rpy="0 0 0" />
      <mass
        value="0.0273093985570947" />
      <inertia
        ixx="8.52366028592721E-06"
        ixy="3.41683380899422E-19"
        ixz="3.18003675694284E-07"
        iyy="6.91333280651081E-06"
        iyz="7.37726682706417E-19"
        izz="2.24270431912283E-06" />
    </inertial>
    <visual>
      <origin
        xyz="0 0 0"
        rpy="0 0 0" />
      <geometry>
        <mesh
          filename="/home/takuma/code/isaaclab_rl_wearglove/assets/nextage_description/urdf/meshes/outer_finger_fine.STL" />
      </geometry>
      <material
        name="">
        <color
          rgba="0.1 0.1 0.1 1" />
      </material>
    </visual>
    <collision>
      <origin
        xyz="0 0 0"
        rpy="0 0 0" />
      <geometry>
        <mesh
          filename="/home/takuma/code/isaaclab_rl_wearglove/assets/nextage_description/urdf/meshes/outer_finger_coarse.STL" />
      </geometry>
    </collision>
  </link>
  <joint
    name="right_outer_finger_joint_L"
    type="fixed">
    <origin
      xyz="0.0317095909367246 0 -0.0016013564954687"
      rpy="0 0 0" />
    <parent
      link="right_outer_knuckle_L" />
    <child
      link="right_outer_finger_L" />
    <axis
      xyz="0 1 0" />
  </joint>

  <!-- other hand -->
   <link
    name="robotiq_85_base_link_R">
    <inertial>
      <origin
        xyz="0.00021987 -2.3546E-10 0.030163"
        rpy="0 0 0" />
      <mass
        value="0.30915" />
      <inertia
        ixx="0.00028972"
        ixy="-5.7879E-10"
        ixz="-1.8543E-06"
        iyy="0.00030737"
        iyz="1.682E-12"
        izz="0.00019914" />
    </inertial>
    <visual>
      <origin
        xyz="0 0 0"
        rpy="0 0 0" />
      <geometry>
        <mesh
          filename="/home/takuma/code/isaaclab_rl_wearglove/assets/nextage_description/urdf/meshes/robotiq_85_base_link_fine.STL" />
      </geometry>
      <material
        name="">
        <color
          rgba="0.1 0.1 0.1 1" />
      </material>
    </visual>
    <collision>
      <origin
        xyz="0 0 0"
        rpy="0 0 0" />
      <geometry>
        <mesh
          filename="/home/takuma/code/isaaclab_rl_wearglove/assets/nextage_description/urdf/meshes/robotiq_85_base_link_coarse.STL" />
      </geometry>
    </collision>
  </link>
  <link
    name="left_outer_knuckle">
    <inertial>
      <origin
        xyz="0.0178331863169983 3.68915177224286E-11 0.0021442477325704"
        rpy="0 0 0" />
      <mass
        value="0.00684838849434396" />
      <inertia
        ixx="2.66832029033166E-07"
        ixy="1.66142314639824E-15"
        ixz="1.45945633322873E-07"
        iyy="1.3889233257419E-06"
        iyz="2.82951161241588E-15"
        izz="1.26603336914415E-06" />
    </inertial>
    <visual>
      <origin
        xyz="0 0 0"
        rpy="0 0 0" />
      <geometry>
        <mesh
          filename="/home/takuma/code/isaaclab_rl_wearglove/assets/nextage_description/urdf/meshes/outer_knuckle_fine.STL" />
      </geometry>
      <material
        name="">
        <color
          rgba="0.1 0.1 0.1 1" />
      </material>
    </visual>
    <collision>
      <origin
        xyz="0 0 0"
        rpy="0 0 0" />
      <geometry>
        <mesh
          filename="/home/takuma/code/isaaclab_rl_wearglove/assets/nextage_description/urdf/meshes/outer_knuckle_coarse.STL" />
      </geometry>
    </collision>
  </link>
  <joint
    name="finger_joint"
    type="revolute">
    <origin
      xyz="0.0306011444260539 0 0.0627920162695395"
      rpy="0 0 0" />
    <parent
      link="robotiq_85_base_link_R" />
    <child
      link="left_outer_knuckle" />
    <axis
      xyz="0 -1 0" />
    <limit
	  lower="0"
      upper="0.725"
      velocity="2.0"
      effort="1000" />
  </joint>
  <link
    name="left_outer_finger">
    <inertial>
      <origin
        xyz="0.00131451599174296 2.88942057994543E-15 0.0215404163180413"
        rpy="0 0 0" />
      <mass
        value="0.0273093985570947" />
      <inertia
        ixx="8.51629628283022E-06"
        ixy="2.58174336207405E-19"
        ixz="3.83829504344079E-07"
        iyy="6.9133328065108E-06"
        iyz="-7.58589926143789E-19"
        izz="2.25006832221981E-06" />
    </inertial>
    <visual>
      <origin
        xyz="0 0 0"
        rpy="0 0 0" />
      <geometry>
        <mesh
          filename="/home/takuma/code/isaaclab_rl_wearglove/assets/nextage_description/urdf/meshes/outer_finger_fine.STL" />
      </geometry>
      <material
        name="">
        <color
          rgba="0.1 0.1 0.1 1" />
      </material>
    </visual>
    <collision>
      <origin
        xyz="0 0 0"
        rpy="0 0 0" />
      <geometry>
        <mesh
          filename="/home/takuma/code/isaaclab_rl_wearglove/assets/nextage_description/urdf/meshes/outer_finger_coarse.STL" />
      </geometry>
    </collision>
  </link>
  <joint
    name="left_outer_finger_joint"
    type="fixed">
    <origin
      xyz="0.0316910442266543 0 -0.00193396375724605"
      rpy="0 0 0" />
    <parent
      link="left_outer_knuckle" />
    <child
      link="left_outer_finger" />
    <axis
      xyz="0 -1 0" />
  </joint>
  <!-- <link
    name="left_inner_knuckle">
    <inertial>
      <origin
        xyz="0.017097546626628 -3.93808524389535E-10 0.0224918438201868"
        rpy="0 0 0" />
      <mass
        value="0.0110930853895903" />
      <inertia
        ixx="4.23392770691541E-06"
        ixy="5.748978936968E-15"
        ixz="1.78855677119788E-06"
        iyy="3.96548790524392E-06"
        iyz="1.05464666369669E-14"
        izz="3.24068002883007E-06" />
    </inertial>
    <visual>
      <origin
        xyz="0 0 0"
        rpy="0 0 0" />
      <geometry>
        <mesh
          filename="/home/takuma/code/isaaclab_rl_wearglove/assets/nextage_description/urdf/meshes/inner_knuckle_fine.STL" />
      </geometry>
      <material
        name="">
        <color
          rgba="0.1 0.1 0.1 1" />
      </material>
    </visual>
    <collision>
      <origin
        xyz="0 0 0"
        rpy="0 0 0" />
      <geometry>
        <mesh
          filename="/home/takuma/code/isaaclab_rl_wearglove/assets/nextage_description/urdf/meshes/inner_knuckle_coarse.STL" />
      </geometry>
    </collision>
  </link>
  <joint
    name="left_inner_knuckle_joint"
    type="revolute">
    <origin
      xyz="0.0127000000001501 0 0.0693074999999639"
      rpy="0 0 0" />
    <parent
      link="robotiq_85_base_link_R" />
    <child
      link="left_inner_knuckle" />
    <axis
      xyz="0 -1 0" />
    <limit
      lower="0"
      upper="0.8757"
      velocity="2.0"
      effort="1000" />
    <mimic 
      joint="finger_joint"
      multiplier="1"
      offset="0" />
  </joint> -->
  <link
    name="left_inner_finger">
    <inertial>
      <origin
        xyz="0.0060275613594574 -6.29183141465421E-15 0.00669925693133241"
        rpy="0 0 0" />
      <mass
        value="0.00724255346165745" />
      <inertia
        ixx="1.47824274053603E-06"
        ixy="-3.94884463570303E-19"
        ixz="-3.45268847648622E-07"
        iyy="1.70064480838395E-06"
        iyz="3.5059838910097E-19"
        izz="4.77151336838364E-07" />
    </inertial>
    <visual>
      <origin
        xyz="0 0 0"
        rpy="0 0 0" />
      <geometry>
        <mesh
          filename="/home/takuma/code/isaaclab_rl_wearglove/assets/nextage_description/urdf/meshes/inner_finger_fine.STL" />
      </geometry>
      <material
        name="">
        <color
          rgba="0.1 0.1 0.1 1" />
      </material>
    </visual>
    <collision>
      <origin
        xyz="0 0 0"
        rpy="0 0 0" />
      <geometry>
        <mesh
          filename="/home/takuma/code/isaaclab_rl_wearglove/assets/nextage_description/urdf/meshes/inner_finger_coarse.STL" />
      </geometry>
    </collision>
  </link>
  <joint
    name="left_inner_finger_joint"
    type="revolute">
    <!-- <origin
      xyz="0.034585310861294 0 0.0454970193817975"
      rpy="0 0 0" /> -->
    <origin
      xyz="-0.01500688 0 0.05394647"
      rpy="0 0 0" />
    <!-- <parent
      link="left_inner_knuckle" /> -->
    <parent
      link="left_outer_finger" />
    <child
      link="left_inner_finger" />
    <axis
      xyz="0 -1 0" />
    <!-- <limit
      lower="0"
      upper="0.8757"
      velocity="2.0"
      effort="1000" /> -->
    <limit
      lower="-0.8757"
      upper="0.0"
      velocity="2.0"
      effort="1000" />
    <mimic 
      joint="finger_joint"
      multiplier="-1"
      offset="0" />
  </joint>
  <!-- <link
    name="right_inner_knuckle">
    <inertial>
      <origin
        xyz="0.0168606186773776 3.93808471820465E-10 0.0226699950793434"
        rpy="0 0 0" />
      <mass
        value="0.0110930853895903" />
      <inertia
        ixx="4.27134775939882E-06"
        ixy="-8.53568456728898E-15"
        ixz="1.77774229944246E-06"
        iyy="3.96548790524392E-06"
        iyz="-8.45108024914164E-15"
        izz="3.20325997634666E-06" />
    </inertial>
    <visual>
      <origin
        xyz="0 0 0"
        rpy="0 0 0" />
      <geometry>
        <mesh
          filename="/home/takuma/code/isaaclab_rl_wearglove/assets/nextage_description/urdf/meshes/inner_knuckle_fine.STL" />
      </geometry>
      <material
        name="">
        <color
          rgba="0.1 0.1 0.1 1" />
      </material>
    </visual>
    <collision>
      <origin
        xyz="0 0 0"
        rpy="0 0 0" />
      <geometry>
        <mesh
          filename="/home/takuma/code/isaaclab_rl_wearglove/assets/nextage_description/urdf/meshes/inner_knuckle_coarse.STL" />
      </geometry>
    </collision>
  </link>
  <joint
    name="right_inner_knuckle_joint"
    type="revolute">
    <origin
      xyz="-0.0126999999998499 0 0.0693075000000361"
      rpy="0 0 3.14159265358979" />
    <parent
      link="robotiq_85_base_link_R" />
    <child
      link="right_inner_knuckle" />
    <axis
      xyz="0 1 0" />
    <limit
      lower="-0.8757"
      upper="0.0"
      velocity="2.0"
      effort="1000" />
    <mimic 
      joint="finger_joint"
      multiplier="-1"
      offset="0" />
  </joint> -->
  <link
    name="right_inner_finger">
    <inertial>
      <origin
        xyz="0.00602756228812038 -6.47284509480176E-15 0.00669925609578108"
        rpy="0 0 0" />
      <mass
        value="0.00724255346165744" />
      <inertia
        ixx="1.47824283625957E-06"
        ixy="-3.95952064019123E-19"
        ixz="-3.45268708875543E-07"
        iyy="1.70064480838394E-06"
        iyz="3.55286507960029E-19"
        izz="4.77151241114822E-07" />
    </inertial>
    <visual>
      <origin
        xyz="0 0 0"
        rpy="0 0 0" />
      <geometry>
        <mesh
          filename="/home/takuma/code/isaaclab_rl_wearglove/assets/nextage_description/urdf/meshes/inner_finger_fine.STL" />
      </geometry>
      <material
        name="">
        <color
          rgba="0.1 0.1 0.1 1" />
      </material>
    </visual>
    <collision>
      <origin
        xyz="0 0 0"
        rpy="0 0 0" />
      <geometry>
        <mesh
          filename="/home/takuma/code/isaaclab_rl_wearglove/assets/nextage_description/urdf/meshes/inner_finger_coarse.STL" />
      </geometry>
    </collision>
  </link>
  <joint
    name="right_inner_finger_joint"
    type="revolute">
    <!-- <origin
      xyz="0.0341060475457406 0 0.0458573878541688"
      rpy="0 0 0" /> -->
    <origin
      xyz="-0.0155046878 0 0.0539742281"
      rpy="0 0 0" />
    <parent
      link="right_outer_finger" />
    <child
      link="right_inner_finger" />
    <axis
      xyz="0 1 0" />
    <limit
      lower="0"
      upper="0.8757"
      velocity="2.0"
      effort="1000" />
    <mimic 
      joint="finger_joint"
      multiplier="1"
      offset="0" />
  </joint>
  <link
    name="right_outer_knuckle">
    <inertial>
      <origin
        xyz="0.0178097074051638 3.60493211424024E-11 0.00233123458346721"
        rpy="0 0 0" />
      <mass
        value="0.00684838849401352" />
      <inertia
        ixx="2.70004361573169E-07"
        ixy="1.59579467624491E-15"
        ixz="1.56396493788199E-07"
        iyy="1.38892332558312E-06"
        iyz="2.82357800318817E-15"
        izz="1.26286103637978E-06" />
    </inertial>
    <visual>
      <origin
        xyz="0 0 0"
        rpy="0 0 0" />
      <geometry>
        <mesh
          filename="/home/takuma/code/isaaclab_rl_wearglove/assets/nextage_description/urdf/meshes/outer_knuckle_fine.STL" />
      </geometry>
      <material
        name="">
        <color
          rgba="0.1 0.1 0.1 1" />
      </material>
    </visual>
    <collision>
      <origin
        xyz="0 0 0"
        rpy="0 0 0" />
      <geometry>
        <mesh
          filename="/home/takuma/code/isaaclab_rl_wearglove/assets/nextage_description/urdf/meshes/outer_knuckle_coarse.STL" />
      </geometry>
    </collision>
  </link>
  <joint
    name="right_outer_knuckle_joint"
    type="revolute">
    <origin
      xyz="-0.0306011444258893 0 0.0627920162695395"
      rpy="0 0 3.14159265358979" />
    <parent
      link="robotiq_85_base_link_R" />
    <child
      link="right_outer_knuckle" />
    <axis
      xyz="0 1 0" />
    <limit
      lower="-0.8757"
      upper="0.0"
      velocity="2.0"
      effort="1000" />
    <mimic 
      joint="finger_joint"
      multiplier="-1"
      offset="0" />
  </joint>
  <link
    name="right_outer_finger">
    <inertial>
      <origin
        xyz="0.00108844269639009 -2.611488350845E-15 0.0215530225245502"
        rpy="0 0 0" />
      <mass
        value="0.0273093985570947" />
      <inertia
        ixx="8.52366028592721E-06"
        ixy="3.41683380899422E-19"
        ixz="3.18003675694284E-07"
        iyy="6.91333280651081E-06"
        iyz="7.37726682706417E-19"
        izz="2.24270431912283E-06" />
    </inertial>
    <visual>
      <origin
        xyz="0 0 0"
        rpy="0 0 0" />
      <geometry>
        <mesh
          filename="/home/takuma/code/isaaclab_rl_wearglove/assets/nextage_description/urdf/meshes/outer_finger_fine.STL" />
      </geometry>
      <material
        name="">
        <color
          rgba="0.1 0.1 0.1 1" />
      </material>
    </visual>
    <collision>
      <origin
        xyz="0 0 0"
        rpy="0 0 0" />
      <geometry>
        <mesh
          filename="/home/takuma/code/isaaclab_rl_wearglove/assets/nextage_description/urdf/meshes/outer_finger_coarse.STL" />
      </geometry>
    </collision>
  </link>
  <joint
    name="right_outer_finger_joint"
    type="fixed">
    <origin
      xyz="0.0317095909367246 0 -0.0016013564954687"
      rpy="0 0 0" />
    <parent
      link="right_outer_knuckle" />
    <child
      link="right_outer_finger" />
    <axis
      xyz="0 1 0" />
  </joint>
  
</robot>
