<?xml version="1.0" ?>
<!-- =================================================================================== -->
<!-- |    This document was autogenerated by xacro from load_robot.urdf.xacro          | -->
<!-- |    EDITING THIS FILE BY HAND IS NOT RECOMMENDED                                 | -->
<!-- =================================================================================== -->
<robot name="torobo">
  <!-- <material name="black">
    <color rgba="0.0 0.0 0.0 1.0"/>
  </material>
  <material name="blue">
    <color rgba="0.0 0.0 0.8 1.0"/>
  </material>
  <material name="green">
    <color rgba="0.0 0.8 0.0 1.0"/>
  </material>
  <material name="grey">
    <color rgba="0.2 0.2 0.2 1.0"/>
  </material>
  <material name="light_grey">
    <color rgba="0.5 0.5 0.5 1.0"/>
  </material>
  <material name="dark_grey">
    <color rgba="0.3 0.3 0.3 1.0"/>
  </material>
  <material name="orange">
    <color rgba="1.0 0.4235294117647059 0.0392156862745098 1.0"/>
  </material>
  <material name="brown">
    <color rgba="0.8705882352941177 0.8117647058823529 0.7647058823529411 1.0"/>
  </material>
  <material name="red">
    <color rgba="0.8 0.0 0.0 1.0"/>
  </material>
  <material name="white">
    <color rgba="1.0 1.0 1.0 1.0"/>
  </material>
  <material name="clear_color">
    <color rgba="0.5 0.5 0.5 0.1"/>
  </material> -->

  <link name="world"/>
  <joint name="base_joint_trans_x" type="prismatic">
    <origin rpy="0 0 0" xyz="0 0 0"/>
    <parent link="world"/>
    <child link="base_link_trans_x"/>
    <axis xyz="1 0 0"/>
    <limit acceleration="10" effort="600" jerk="10" lower="-1e+4" upper="1e+4" velocity="10"/>
  </joint>
  <link name="base_link_trans_x">
    <inertial>
      <mass value="10"/>
      <inertia ixx="1" ixy="0" ixz="0" iyy="1" iyz="0" izz="1"/>
    </inertial>
  </link>
  <joint name="base_joint_trans_y" type="prismatic">
    <parent link="base_link_trans_x"/>
    <child link="base_link_trans_y"/>
    <axis xyz="0 1 0"/>
    <limit acceleration="10" effort="600" jerk="10" lower="-1e+4" upper="1e+4" velocity="10"/>
  </joint>
  <link name="base_link_trans_y">
    <inertial>
      <mass value="10"/>
      <inertia ixx="1" ixy="0" ixz="0" iyy="1" iyz="0" izz="1"/>
    </inertial>
  </link>
  <joint name="base_joint_rot_yaw" type="continuous">
    <parent link="base_link_trans_y"/>
    <child link="base_link_rot_yaw"/>
    <axis xyz="0 0 1"/>
    <limit acceleration="10" effort="600" jerk="10" lower="-10" upper="10" velocity="10"/>
  </joint>
  <link name="base_link_rot_yaw">
    <inertial>
      <mass value="1e-5"/>
      <inertia ixx="1e-8" ixy="0" ixz="0" iyy="1e-8" iyz="0" izz="1e-8"/>
    </inertial>
  </link>
  <joint name="base_footprint_joint" type="fixed">
    <parent link="base_link_rot_yaw"/>
    <child link="base_footprint"/>
  </joint>
  <link name="base_footprint">
    <inertial>
      <mass value="1e-5"/>
      <inertia ixx="1e-8" ixy="0" ixz="0" iyy="1e-8" iyz="0" izz="1e-8"/>
    </inertial>
  </link>
  
  <joint name="base_joint" type="fixed">
    <origin rpy="0 0 0" xyz="0 0 0"/>
    <parent link="base_footprint"/>
    <child link="base_link"/>
  </joint>
  <link name="base_link">
    <visual>
      <geometry>
        <mesh filename="/home/takuma/code/isaaclab_rl_wearglove/assets/airec/meshes/base/TRBD-B-A-001-4/DAE/base_link.dae" scale="1.0 1.0 1.0"/>
      </geometry>
      <material name="white"/>
    </visual>
    <collision>
      <geometry>
        <mesh filename="/home/takuma/code/isaaclab_rl_wearglove/assets/airec/meshes/base/TRBD-B-A-001-4/STL/base_link.stl" scale="1.0 1.0 1.0"/>
      </geometry>
    </collision>
    <inertial>
      <origin xyz="-0.004766 0.002382 0.150411"/>
      <mass value="51.684"/>
      <inertia ixx="1.439413e+0" ixy="8.539427e-4" ixz="-5.785410e-3" iyy="1.349905e+0" iyz="-9.305572e-3" izz="2.133790e+0"/>
    </inertial>
  </link>
  <!-- link_tip -->
  <joint name="base/joint_tip" type="fixed">
    <parent link="base_link"/>
    <child link="base/link_tip"/>
    <origin rpy="0 0 0" xyz="0 0 0.29510000000000003"/>
  </joint>
  <link name="base/link_tip"/>
  <joint name="base_front_right_wheel/joint" type="continuous">
    <origin rpy="1.5707963267948966 0 0.7853981633974483" xyz="0.20152543263816602 -0.20152543263816602 0.1016"/>
    <axis xyz="0 0 1"/>
    <parent link="base_link"/>
    <child link="base_front_right_wheel/link"/>
    <limit acceleration="52.35987755982988" effort="50" jerk="261.79938779914943" velocity="12.217304763960305"/>
  </joint>
  <link name="base_front_right_wheel/link">
    <visual>
      <geometry>
        <mesh filename="/home/takuma/code/isaaclab_rl_wearglove/assets/airec/meshes/wheel/QLM-20/DAE/wheel_link.dae" scale="1 1 1"/>
      </geometry>
      <material name="grey"/>
    </visual>
    <collision>
      <geometry>
        <cylinder length="0.001" radius="0.001"/>
      </geometry>
    </collision>
    <inertial>
      <origin xyz="0.000000 0.000000 0.000000"/>
      <mass value="1.600000"/>
      <inertia ixx="2.983791e-3" ixy="-4.830000e-8" ixz="-2.430000e-8" iyy="2.983810e-3" iyz="9.700000e-9" izz="5.578630e-3"/>
    </inertial>
  </link>
  <joint name="base_front_right_wheel/joint_inner_barrel_center" type="fixed">
    <parent link="base_front_right_wheel/link"/>
    <child link="base_front_right_wheel/link_inner_barrel_center"/>
    <origin rpy="0 0 0" xyz="0 0 -0.018"/>
  </joint>
  <link name="base_front_right_wheel/link_inner_barrel_center"/>
  <joint name="base_front_right_wheel/joint_outer_barrel_center" type="fixed">
    <parent link="base_front_right_wheel/link"/>
    <child link="base_front_right_wheel/link_outer_barrel_center"/>
    <origin rpy="0 0 0" xyz="0 0 0.018"/>
  </joint>
  <link name="base_front_right_wheel/link_outer_barrel_center"/>

  <joint name="base_front_left_wheel/joint" type="continuous">
    <origin rpy="1.5707963267948966 0 2.356194490192345" xyz="0.20152543263816602 0.20152543263816602 0.1016"/>
    <axis xyz="0 0 1"/>
    <parent link="base_link"/>
    <child link="base_front_left_wheel/link"/>
    <limit acceleration="52.35987755982988" effort="50" jerk="261.79938779914943" velocity="12.217304763960305"/>
  </joint>
  <link name="base_front_left_wheel/link">
    <visual>
      <geometry>
        <mesh filename="/home/takuma/code/isaaclab_rl_wearglove/assets/airec/meshes/wheel/QLM-20/DAE/wheel_link.dae" scale="1 1 1"/>
      </geometry>
      <material name="grey"/>
    </visual>
    <collision>
      <geometry>
        <cylinder length="0.001" radius="0.001"/>
      </geometry>
    </collision>
    <inertial>
      <origin xyz="0.000000 0.000000 0.000000"/>
      <mass value="1.600000"/>
      <inertia ixx="2.983791e-3" ixy="-4.830000e-8" ixz="-2.430000e-8" iyy="2.983810e-3" iyz="9.700000e-9" izz="5.578630e-3"/>
    </inertial>
  </link>
  <joint name="base_front_left_wheel/joint_inner_barrel_center" type="fixed">
    <parent link="base_front_left_wheel/link"/>
    <child link="base_front_left_wheel/link_inner_barrel_center"/>
    <origin rpy="0 0 0" xyz="0 0 -0.018"/>
  </joint>
  <link name="base_front_left_wheel/link_inner_barrel_center"/>
  <joint name="base_front_left_wheel/joint_outer_barrel_center" type="fixed">
    <parent link="base_front_left_wheel/link"/>
    <child link="base_front_left_wheel/link_outer_barrel_center"/>
    <origin rpy="0 0 0" xyz="0 0 0.018"/>
  </joint>
  <link name="base_front_left_wheel/link_outer_barrel_center"/>

  <joint name="base_rear_right_wheel/joint" type="continuous">
    <origin rpy="1.5707963267948966 0 5.497787143782138" xyz="-0.20152543263816602 -0.20152543263816602 0.1016"/>
    <axis xyz="0 0 1"/>
    <parent link="base_link"/>
    <child link="base_rear_right_wheel/link"/>
    <limit acceleration="52.35987755982988" effort="50" jerk="261.79938779914943" velocity="12.217304763960305"/>
  </joint>
  <link name="base_rear_right_wheel/link">
    <visual>
      <geometry>
        <mesh filename="/home/takuma/code/isaaclab_rl_wearglove/assets/airec/meshes/wheel/QLM-20/DAE/wheel_link.dae" scale="1 1 1"/>
      </geometry>
      <material name="grey"/>
    </visual>
    <collision>
      <geometry>
        <cylinder length="0.001" radius="0.001"/>
      </geometry>
    </collision>
    <inertial>
      <origin xyz="0.000000 0.000000 0.000000"/>
      <mass value="1.600000"/>
      <inertia ixx="2.983791e-3" ixy="-4.830000e-8" ixz="-2.430000e-8" iyy="2.983810e-3" iyz="9.700000e-9" izz="5.578630e-3"/>
    </inertial>
  </link>
  <joint name="base_rear_right_wheel/joint_inner_barrel_center" type="fixed">
    <parent link="base_rear_right_wheel/link"/>
    <child link="base_rear_right_wheel/link_inner_barrel_center"/>
    <origin rpy="0 0 0" xyz="0 0 -0.018"/>
  </joint>
  <link name="base_rear_right_wheel/link_inner_barrel_center"/>
  <joint name="base_rear_right_wheel/joint_outer_barrel_center" type="fixed">
    <parent link="base_rear_right_wheel/link"/>
    <child link="base_rear_right_wheel/link_outer_barrel_center"/>
    <origin rpy="0 0 0" xyz="0 0 0.018"/>
  </joint>
  <link name="base_rear_right_wheel/link_outer_barrel_center"/>
  
  <joint name="base_rear_left_wheel/joint" type="continuous">
    <origin rpy="1.5707963267948966 0 3.9269908169872414" xyz="-0.20152543263816602 0.20152543263816602 0.1016"/>
    <axis xyz="0 0 1"/>
    <parent link="base_link"/>
    <child link="base_rear_left_wheel/link"/>
    <limit acceleration="52.35987755982988" effort="50" jerk="261.79938779914943" velocity="12.217304763960305"/>
  </joint>
  <link name="base_rear_left_wheel/link">
    <visual>
      <geometry>
        <mesh filename="/home/takuma/code/isaaclab_rl_wearglove/assets/airec/meshes/wheel/QLM-20/DAE/wheel_link.dae" scale="1 1 1"/>
      </geometry>
      <material name="grey"/>
    </visual>
    <collision>
      <geometry>
        <cylinder length="0.001" radius="0.001"/>
      </geometry>
    </collision>
    <inertial>
      <origin xyz="0.000000 0.000000 0.000000"/>
      <mass value="1.600000"/>
      <inertia ixx="2.983791e-3" ixy="-4.830000e-8" ixz="-2.430000e-8" iyy="2.983810e-3" iyz="9.700000e-9" izz="5.578630e-3"/>
    </inertial>
  </link>
  <joint name="base_rear_left_wheel/joint_inner_barrel_center" type="fixed">
    <parent link="base_rear_left_wheel/link"/>
    <child link="base_rear_left_wheel/link_inner_barrel_center"/>
    <origin rpy="0 0 0" xyz="0 0 -0.018"/>
  </joint>
  <link name="base_rear_left_wheel/link_inner_barrel_center"/>
  <joint name="base_rear_left_wheel/joint_outer_barrel_center" type="fixed">
    <parent link="base_rear_left_wheel/link"/>
    <child link="base_rear_left_wheel/link_outer_barrel_center"/>
    <origin rpy="0 0 0" xyz="0 0 0.018"/>
  </joint>
  <link name="base_rear_left_wheel/link_outer_barrel_center"/>
  

  <!-- =============== Constants =============== -->
  <joint name="torso/root" type="fixed">
    <origin rpy="0 0 0" xyz="0.025 0 0"/>
    <parent link="base/link_tip"/>
    <child link="torso/link_0"/>
  </joint>
  <link name="torso/link_0">
    <visual>
      <geometry>
        <mesh filename="/home/takuma/code/isaaclab_rl_wearglove/assets/airec/meshes/torso/TRBD-T-A-001-3/DAE/link0.dae" scale="1.0 1.0 1.0"/>
      </geometry>
      <material name="white"/>
      <origin xyz="0 0 0"/>
    </visual>
    <collision>
      <geometry>
        <mesh filename="/home/takuma/code/isaaclab_rl_wearglove/assets/airec/meshes/torso/TRBD-T-A-001-3/STL/link0.stl" scale="1.0 1.0 1.0"/>
      </geometry>
      <origin xyz="0 0 0"/>
    </collision>
    <inertial>
      <origin xyz="-0.000004 0.007321 0.084459"/>
      <mass value="11.331750"/>
      <inertia ixx="7.123330e-2" ixy="1.270600e-6" ixz="3.192000e-7" iyy="8.264497e-2" iyz="-4.063324e-3" izz="7.749736e-2"/>
    </inertial>
  </link>
  <joint name="torso/joint_1" type="revolute">
    <parent link="torso/link_0"/>
    <child link="torso/link_1"/>
    <origin rpy="-1.5707963267948966 -1.5707963267948966 0" xyz="0 0 0.125"/>
    <axis xyz="0 0 1"/>
    <limit acceleration="5.235987755982989" effort="700" jerk="26.17993877991494" lower="-0.7853981633974483" upper="0.7853981633974483" velocity="0.8726646259971648"/>
  </joint>
  <link name="torso/link_1">
    <visual>
      <geometry>
        <mesh filename="/home/takuma/code/isaaclab_rl_wearglove/assets/airec/meshes/torso/TRBD-T-A-001-3/DAE/link1.dae" scale="1.0 1.0 1.0"/>
      </geometry>
      <material name="white"/>
    </visual>
    <collision>
      <geometry>
        <mesh filename="/home/takuma/code/isaaclab_rl_wearglove/assets/airec/meshes/torso/TRBD-T-A-001-3/STL/link1.stl" scale="1.0 1.0 1.0"/>
      </geometry>
    </collision>
    <inertial>
      <origin xyz="0.302405 -0.001727 -0.012176"/>
      <mass value="14.063142"/>
      <inertia ixx="7.771230e-2" ixy="1.052554e-2" ixz="-4.101577e-4" iyy="5.451814e-1" iyz="2.950887e-4" izz="5.222185e-1"/>
    </inertial>
  </link>
  <joint name="torso/joint_2" type="revolute">
    <parent link="torso/link_1"/>
    <child link="torso/link_2"/>
    <origin rpy="0 0 1.5707963267948966" xyz="0.500 0 0"/>
    <axis xyz="0 0 1"/>
    <limit acceleration="8.726646259971647" effort="700" jerk="43.63323129985824" lower="-0.8726646259971648" upper="1.8325957145940461" velocity="1.5707963267948966"/>
  </joint>
  <link name="torso/link_2">
    <visual>
      <geometry>
        <mesh filename="/home/takuma/code/isaaclab_rl_wearglove/assets/airec/meshes/torso/TRBD-T-A-001-3/DAE/link2.dae" scale="1.0 1.0 1.0"/>
      </geometry>
      <material name="white"/>
    </visual>
    <collision>
      <geometry>
        <mesh filename="/home/takuma/code/isaaclab_rl_wearglove/assets/airec/meshes/torso/TRBD-T-A-001-3/STL/link2.stl" scale="1.0 1.0 1.0"/>
      </geometry>
    </collision>
    <inertial>
      <origin xyz="0.000229 -0.043577 0.008591"/>
      <mass value="9.816814"/>
      <inertia ixx="6.166941e-2" ixy="6.672710e-5" ixz="-6.442040e-5" iyy="3.334431e-2" iyz="-4.176563e-3" izz="6.751027e-2"/>
    </inertial>
  </link>
  <joint name="torso/joint_3" type="revolute">
    <parent link="torso/link_2"/>
    <child link="torso/link_3"/>
    <origin rpy="1.5707963267948966 0 0" xyz="0 0 0"/>
    <axis xyz="0 0 1"/>
    <limit acceleration="8.726646259971647" effort="700" jerk="43.63323129985824" lower="-1.7453292519943295" upper="1.7453292519943295" velocity="1.5707963267948966"/>
  </joint>
  <link name="torso/link_3">
    <visual>
      <geometry>
        <!-- <mesh filename="/home/takuma/code/isaaclab_rl_wearglove/assets/airec/meshes/torso/${torso_type}/DAE/link3.dae" scale="${vis_mesh_scale}"/> -->
        <mesh filename="/home/takuma/code/isaaclab_rl_wearglove/assets/airec/meshes/torso/TRBD-T-A-001-3/DAE/link3_eyebolt.dae" scale="1.0 1.0 1.0"/>
      </geometry>
      <material name="white"/>
    </visual>
    <collision>
      <geometry>
        <!-- <mesh filename="/home/takuma/code/isaaclab_rl_wearglove/assets/airec/meshes/torso/${torso_type}/STL/link3.stl" scale="${col_mesh_scale}"/> -->
        <mesh filename="/home/takuma/code/isaaclab_rl_wearglove/assets/airec/meshes/torso/TRBD-T-A-001-3/STL/link3_eyebolt.stl" scale="1.0 1.0 1.0"/>
      </geometry>
    </collision>
    <inertial>
      <origin xyz="-0.013893 -0.001794 0.3"/>
      <mass value="19.777173"/>
      <inertia ixx="2.429739e-1" ixy="-1.977960e-3" ixz="1.424146e-2" iyy="2.554216e-1" iyz="7.125594e-4" izz="1.704083e-1"/>
    </inertial>
  </link>
  <joint name="torso/waist_top_joint" type="fixed">
    <parent link="torso/link_3"/>
    <child link="torso/waist_top_link"/>
    <origin rpy="0 0 0" xyz="0 0 0"/>
  </joint>
  <link name="torso/waist_top_link"/>
  <joint name="torso/left_shoulder_joint" type="fixed">
    <parent link="torso/link_3"/>
    <child link="torso/left_shoulder_link"/>
    <origin rpy="1.5707963267948966 1.5707963267948966 0" xyz="0 0.0859 0.400"/>
  </joint>
  <link name="torso/left_shoulder_link"/>
  <joint name="torso/right_shoulder_joint" type="fixed">
    <parent link="torso/link_3"/>
    <child link="torso/right_shoulder_link"/>
    <origin rpy="1.5707963267948966 1.5707963267948966 0" xyz="0 -0.0859 0.400"/>
  </joint>
  <link name="torso/right_shoulder_link"/>
  <joint name="torso/joint_tip" type="fixed">
    <parent link="torso/link_3"/>
    <child link="torso/link_tip"/>
    <origin rpy="0 0 0" xyz="0 0 0.545"/>
  </joint>
  <link name="torso/link_tip"/>

  
  <joint name="head/root" type="fixed">
    <origin rpy="0 0 0" xyz="0 0 0"/>
    <parent link="torso/link_tip"/>
    <child link="head/link_0"/>
  </joint>
  <link name="head/link_0">
    <inertial>
      <mass value="1e-5"/>
      <inertia ixx="1e-8" ixy="0" ixz="0" iyy="1e-8" iyz="0" izz="1e-8"/>
    </inertial>
  </link>
  <joint name="head/joint_1" type="revolute">
    <parent link="head/link_0"/>
    <child link="head/link_1"/>
    <origin rpy="0 0 0" xyz="0 0 0"/>
    <axis xyz="0 0 1"/>
    <limit acceleration="52.35987755982988" effort="8" jerk="261.79938779914943" lower="-1.5707963267948966" upper="1.5707963267948966" velocity="5.585053606381854"/>
  </joint>
  <link name="head/link_1">
    <visual>
      <geometry>
        <mesh filename="/home/takuma/code/isaaclab_rl_wearglove/assets/airec/meshes/head/TRBD-H-A-001-3/DAE/link1.dae" scale="1.0 1.0 1.0"/>
      </geometry>
      <material name="white"/>
    </visual>
    <collision>
      <geometry>
        <mesh filename="/home/takuma/code/isaaclab_rl_wearglove/assets/airec/meshes/head/TRBD-H-A-001-3/STL/link1.stl" scale="1.0 1.0 1.0"/>
      </geometry>
    </collision>
    <inertial>
      <origin xyz="-0.012538 0.001215 -0.011777"/>
      <mass value="0.584413"/>
      <inertia ixx="5.202001e-4" ixy="8.304500e-6" ixz="1.099535e-4" iyy="6.604397e-4" iyz="-1.295500e-5" izz="4.587926e-4"/>
    </inertial>
  </link>
  <joint name="head/joint_2" type="revolute">
    <parent link="head/link_1"/>
    <child link="head/link_2"/>
    <origin rpy="0 -1.5707963267948966 -1.5707963267948966" xyz="-0.020 0 0"/>
    <axis xyz="0 0 1"/>
    <limit acceleration="52.35987755982988" effort="8" jerk="261.79938779914943" lower="-0.8726646259971648" upper="0.8726646259971648" velocity="4.71238898038469"/>
  </joint>
  <link name="head/link_2">
    <visual>
      <geometry>
        <mesh filename="/home/takuma/code/isaaclab_rl_wearglove/assets/airec/meshes/head/TRBD-H-A-001-3/DAE/link2.dae" scale="1.0 1.0 1.0"/>
      </geometry>
      <material name="white"/>
    </visual>
    <collision>
      <geometry>
        <mesh filename="/home/takuma/code/isaaclab_rl_wearglove/assets/airec/meshes/head/TRBD-H-A-001-3/STL/link2.stl" scale="1.0 1.0 1.0"/>
      </geometry>
    </collision>
    <inertial>
      <origin xyz="0.024516 -0.025964 -0.002062"/>
      <mass value="0.437673"/>
      <inertia ixx="5.009059e-4" ixy="1.895133e-4" ixz="-3.169870e-5" iyy="4.956662e-4" iyz="2.823320e-5" izz="5.764618e-4"/>
    </inertial>
  </link>
  <joint name="head/joint_3" type="revolute">
    <parent link="head/link_2"/>
    <child link="head/link_3"/>
    <origin rpy="-1.5707963267948966 0 0" xyz="0.041 0 0"/>
    <axis xyz="0 0 1"/>
    <limit acceleration="52.35987755982988" effort="8" jerk="261.79938779914943" lower="-0.6981317007977318" upper="0.6981317007977318" velocity="3.839724354387525"/>
  </joint>
  <link name="head/link_3">
    <visual>
      <geometry>
        <mesh filename="/home/takuma/code/isaaclab_rl_wearglove/assets/airec/meshes/head/TRBD-H-A-001-3/DAE/link3.dae" scale="1.0 1.0 1.0"/>
      </geometry>
      <material name="white"/>
    </visual>
    <collision>
      <geometry>
        <mesh filename="/home/takuma/code/isaaclab_rl_wearglove/assets/airec/meshes/head/TRBD-H-A-001-3/STL/link3.stl" scale="1.0 1.0 1.0"/>
      </geometry>
    </collision>
    <inertial>
      <origin xyz="0.071102 -0.000399 0.013331"/>
      <mass value="1.428802"/>
      <inertia ixx="6.834467e-3" ixy="4.523020e-5" ixz="-2.659306e-4" iyy="6.403934e-3" iyz="4.426740e-5" izz="3.453605e-3"/>
    </inertial>
  </link>
  <joint name="head/joint_tip" type="fixed">
    <parent link="head/link_3"/>
    <child link="head/link_tip"/>
    <origin rpy="0 -1.5707963267948966 3.141592653589793 " xyz="0 0 0"/>
  </joint>
  <link name="head/link_tip"/>
  <joint name="head/joint_face_center" type="fixed">
    <parent link="head/link_tip"/>
    <child link="head/link_face_center"/>
    <origin rpy="0 0 0" xyz="0.120 0 0.060"/>
  </joint>
  <link name="head/link_face_center"/>
  <!-- Camera -->
  <joint name="head/see3cam_left/camera_joint" type="fixed">
    <origin rpy="0 0 0" xyz="0.120 0.042 0.060"/>
    <parent link="head/link_tip"/>
    <child link="head/see3cam_left/camera_link"/>
    <axis xyz="0 1 0"/>
  </joint>
  <link name="head/see3cam_left/camera_link">
  </link>
  <joint name="head/see3cam_left/camera_color_frame_joint" type="fixed">
    <axis xyz="0 1 0"/>
    <origin rpy="0 0 0" xyz="0 0 0"/>
    <parent link="head/see3cam_left/camera_link"/>
    <child link="head/see3cam_left/camera_color_frame"/>
  </joint>
  <link name="head/see3cam_left/camera_color_frame">
    </link>
  <joint name="head/see3cam_left/camera_color_optical_frame_joint" type="fixed">
    <axis xyz="0 1 0"/>
    <origin rpy="-1.5707963267948966 0 -1.5707963267948966" xyz="0 0 0"/>
    <parent link="head/see3cam_left/camera_color_frame"/>
    <child link="head/see3cam_left/camera_color_optical_frame"/>
  </joint>
  <link name="head/see3cam_left/camera_color_optical_frame">
    </link>
  
  <!-- Camera -->
  <joint name="head/see3cam_right/camera_joint" type="fixed">
    <origin rpy="0 0 0" xyz="0.120 -0.042 0.060"/>
    <parent link="head/link_tip"/>
    <child link="head/see3cam_right/camera_link"/>
    <axis xyz="0 1 0"/>
  </joint>
  <link name="head/see3cam_right/camera_link">
  </link>
  <joint name="head/see3cam_right/camera_color_frame_joint" type="fixed">
    <axis xyz="0 1 0"/>
    <origin rpy="0 0 0" xyz="0 0 0"/>
    <parent link="head/see3cam_right/camera_link"/>
    <child link="head/see3cam_right/camera_color_frame"/>
  </joint>
  <link name="head/see3cam_right/camera_color_frame">
    </link>
  <joint name="head/see3cam_right/camera_color_optical_frame_joint" type="fixed">
    <axis xyz="0 1 0"/>
    <origin rpy="-1.5707963267948966 0 -1.5707963267948966" xyz="0 0 0"/>
    <parent link="head/see3cam_right/camera_color_frame"/>
    <child link="head/see3cam_right/camera_color_optical_frame"/>
  </joint>
  <link name="head/see3cam_right/camera_color_optical_frame">
    </link>
  
  <!-- Camera -->
  <joint name="head/insta360/camera_joint" type="fixed">
    <origin rpy="0 0 0" xyz="0.125 0.0 0.043"/>
    <parent link="head/link_tip"/>
    <child link="head/insta360/camera_link"/>
    <axis xyz="0 1 0"/>
  </joint>
  <link name="head/insta360/camera_link">
  </link>
  <joint name="head/insta360/camera_color_frame_joint" type="fixed">
    <axis xyz="0 1 0"/>
    <origin rpy="0 0 0" xyz="0 0 0"/>
    <parent link="head/insta360/camera_link"/>
    <child link="head/insta360/camera_color_frame"/>
  </joint>
  <link name="head/insta360/camera_color_frame">
    </link>
  <joint name="head/insta360/camera_color_optical_frame_joint" type="fixed">
    <axis xyz="0 1 0"/>
    <origin rpy="-1.5707963267948966 0 -1.5707963267948966" xyz="0 0 0"/>
    <parent link="head/insta360/camera_color_frame"/>
    <child link="head/insta360/camera_color_optical_frame"/>
  </joint>
  <link name="head/insta360/camera_color_optical_frame">
    </link>
  
  <!-- Camera -->
  <joint name="head/sr300/camera_joint" type="fixed">
    <origin rpy="0 0 0" xyz="0.105 0 0.10874"/>
    <parent link="head/link_tip"/>
    <child link="head/sr300/camera_link"/>
    <axis xyz="0 1 0"/>
  </joint>
  <link name="head/sr300/camera_link">
  </link>
  <joint name="head/sr300/camera_color_frame_joint" type="fixed">
    <axis xyz="0 1 0"/>
    <origin rpy="0 0 0" xyz="0.02 0 0"/>
    <parent link="head/sr300/camera_link"/>
    <child link="head/sr300/camera_color_frame"/>
  </joint>
  <link name="head/sr300/camera_color_frame">
    </link>
  <joint name="head/sr300/camera_color_optical_frame_joint" type="fixed">
    <axis xyz="0 1 0"/>
    <origin rpy="-1.5707963267948966 0 -1.5707963267948966" xyz="0 0 0"/>
    <parent link="head/sr300/camera_color_frame"/>
    <child link="head/sr300/camera_color_optical_frame"/>
  </joint>
  <link name="head/sr300/camera_color_optical_frame">
    </link>
  
  <!-- =============== Constants =============== -->
  <joint name="left_arm/root" type="fixed">
    <origin rpy="0 0 0" xyz="0 0 0"/>
    <parent link="torso/left_shoulder_link"/>
    <child link="left_arm/link_0"/>
  </joint>
  <link name="left_arm/link_0">
    <inertial>
      <origin xyz="0.000035 -0.000022 -0.001990"/>
      <mass value="1.803167"/>
      <inertia ixx="2.426334e-3" ixy="4.473000e-7" ixz="-8.480000e-8" iyy="2.426084e-3" iyz="4.440000e-8" izz="2.142324e-3"/>
    </inertial>
  </link>
  <joint name="left_arm/joint_1" type="revolute">
    <parent link="left_arm/link_0"/>
    <child link="left_arm/link_1"/>
    <origin rpy="0 0 0" xyz="0 0 -0.1641"/>
    <axis xyz="0 0 1"/>
    <limit acceleration="27.925268031909273" effort="220" jerk="139.62634015954634" lower="-1.2217304763960306" upper="4.1887902047863905" velocity="2.6179938779914944"/>
  </joint>
  <link name="left_arm/link_1">
    <visual>
      <geometry>
        <mesh filename="/home/takuma/code/isaaclab_rl_wearglove/assets/airec/meshes/arm/TRBD-LA-A-001-7/DAE/link1.dae" scale="1.0 1.0 1.0"/>
      </geometry>
      <material name="white"/>
    </visual>
    <collision>
      <geometry>
        <mesh filename="/home/takuma/code/isaaclab_rl_wearglove/assets/airec/meshes/arm/TRBD-LA-A-001-7/STL/link1.stl" scale="1.0 1.0 1.0"/>
      </geometry>
    </collision>
    <inertial>
      <origin xyz="0.003840 0.000548 0.039985"/>
      <mass value="4.396916"/>
      <inertia ixx="1.841398e-2" ixy="-2.385544e-4" ixz="1.283648e-3" iyy="1.950780e-2" iyz="1.539393e-3" izz="9.370438e-3"/>
    </inertial>
  </link>
  <joint name="left_arm/joint_2" type="revolute">
    <parent link="left_arm/link_1"/>
    <child link="left_arm/link_2"/>
    <origin rpy="0 1.5707963267948966 -1.5707963267948966" xyz="0.010 0 0"/>
    <axis xyz="0 0 1"/>
    <limit acceleration="27.925268031909273" effort="220" jerk="139.62634015954634" lower="-2.1816615649929116" upper="0.3490658503988659" velocity="2.6179938779914944"/>
  </joint>
  <link name="left_arm/link_2">
    <visual>
      <geometry>
        <mesh filename="/home/takuma/code/isaaclab_rl_wearglove/assets/airec/meshes/arm/TRBD-LA-A-001-7/DAE/link2.dae" scale="1.0 1.0 1.0"/>
      </geometry>
      <material name="white"/>
    </visual>
    <collision>
      <geometry>
        <mesh filename="/home/takuma/code/isaaclab_rl_wearglove/assets/airec/meshes/arm/TRBD-LA-A-001-7/STL/link2.stl" scale="1.0 1.0 1.0"/>
      </geometry>
    </collision>
    <inertial>
      <origin xyz="0.005093 0.072288 0.008476"/>
      <mass value="4.970061"/>
      <inertia ixx="4.008293e-2" ixy="-1.371946e-3" ixz="2.173618e-4" iyy="1.337824e-2" iyz="3.067954e-3" izz="3.743154e-2"/>
    </inertial>
  </link>
  <joint name="left_arm/joint_3" type="revolute">
    <parent link="left_arm/link_2"/>
    <child link="left_arm/link_3"/>
    <origin rpy="0 1.5707963267948966 -1.5707963267948966" xyz="0.010 0.335 0"/>
    <axis xyz="0 0 1"/>
    <limit acceleration="38.39724354387525" effort="110" jerk="191.9862177193762" lower="-2.0943951023931953" upper="2.0943951023931953" velocity="3.3161255787892263"/>
  </joint>
  <link name="left_arm/link_3">
    <visual>
      <geometry>
        <mesh filename="/home/takuma/code/isaaclab_rl_wearglove/assets/airec/meshes/arm/TRBD-LA-A-001-7/DAE/link3.dae" scale="1.0 1.0 1.0"/>
      </geometry>
      <material name="white"/>
    </visual>
    <collision>
      <geometry>
        <mesh filename="/home/takuma/code/isaaclab_rl_wearglove/assets/airec/meshes/arm/TRBD-LA-A-001-7/STL/link3.stl" scale="1.0 1.0 1.0"/>
      </geometry>
    </collision>
    <inertial>
      <origin xyz="0.006101 0.001974 0.041100"/>
      <mass value="3.884615"/>
      <inertia ixx="2.115675e-2" ixy="-1.199832e-4" ixz="2.294715e-3" iyy="2.171611e-2" iyz="5.141904e-4" izz="7.974286e-3"/>
    </inertial>
  </link>
  <joint name="left_arm/joint_4" type="revolute">
    <parent link="left_arm/link_3"/>
    <child link="left_arm/link_4"/>
    <origin rpy="1.5707963267948966 0 0" xyz="0.020 0 0"/>
    <axis xyz="0 0 1"/>
    <limit acceleration="38.39724354387525" effort="110" jerk="191.9862177193762" lower="-0.17453292519943295" upper="2.443460952792061" velocity="3.3161255787892263"/>
  </joint>
  <link name="left_arm/link_4">
    <visual>
      <geometry>
        <mesh filename="/home/takuma/code/isaaclab_rl_wearglove/assets/airec/meshes/arm/TRBD-LA-A-001-7/DAE/link4.dae" scale="1.0 1.0 1.0"/>
      </geometry>
      <material name="white"/>
    </visual>
    <collision>
      <geometry>
        <mesh filename="/home/takuma/code/isaaclab_rl_wearglove/assets/airec/meshes/arm/TRBD-LA-A-001-7/STL/link4.stl" scale="1.0 1.0 1.0"/>
      </geometry>
    </collision>
    <inertial>
      <origin xyz="-0.013158 -0.043830 0.004280"/>
      <mass value="3.170001"/>
      <inertia ixx="1.813721e-2" ixy="-1.679090e-3" ixz="-1.819500e-4" iyy="7.972041e-3" iyz="-8.906634e-4" izz="1.645831e-2"/>
    </inertial>
  </link>
  <joint name="left_arm/joint_5" type="revolute">
    <parent link="left_arm/link_4"/>
    <child link="left_arm/link_5"/>
    <origin rpy="0 -1.5707963267948966 -1.5707963267948966" xyz="-0.020 -0.345 0"/>
    <axis xyz="0 0 1"/>
    <limit acceleration="52.35987755982988" effort="50" jerk="261.79938779914943" lower="-2.9670597283903604" upper="2.9670597283903604" velocity="4.014257279586958"/>
  </joint>
  <link name="left_arm/link_5">
    <visual>
      <geometry>
        <mesh filename="/home/takuma/code/isaaclab_rl_wearglove/assets/airec/meshes/arm/TRBD-LA-A-001-7/DAE/link5.dae" scale="1.0 1.0 1.0"/>
      </geometry>
      <material name="white"/>
    </visual>
    <collision>
      <geometry>
        <mesh filename="/home/takuma/code/isaaclab_rl_wearglove/assets/airec/meshes/arm/TRBD-LA-A-001-7/STL/link5.stl" scale="1.0 1.0 1.0"/>
      </geometry>
    </collision>
    <inertial>
      <origin xyz="-0.000023 0.020938 0.116946"/>
      <mass value="2.366366"/>
      <inertia ixx="1.328360e-2" ixy="-2.245700e-6" ixz="3.003300e-6" iyy="1.198735e-2" iyz="3.387750e-3" izz="4.541351e-3"/>
    </inertial>
  </link>
  <joint name="left_arm/joint_6" type="revolute">
    <parent link="left_arm/link_5"/>
    <child link="left_arm/link_6"/>
    <origin rpy="0 1.5707963267948966 -1.5707963267948966" xyz="0 0 0"/>
    <axis xyz="0 0 1"/>
    <limit acceleration="52.35987755982988" effort="50" jerk="261.79938779914943" lower="-1.5707963267948966" upper="1.5707963267948966" velocity="4.014257279586958"/>
  </joint>
  <link name="left_arm/link_6">
    <visual>
      <geometry>
        <mesh filename="/home/takuma/code/isaaclab_rl_wearglove/assets/airec/meshes/arm/TRBD-LA-A-001-7/DAE/link6.dae" scale="1.0 1.0 1.0"/>
      </geometry>
      <material name="white"/>
    </visual>
    <collision>
      <geometry>
        <mesh filename="/home/takuma/code/isaaclab_rl_wearglove/assets/airec/meshes/arm/TRBD-LA-A-001-7/STL/link6.stl" scale="1.0 1.0 1.0"/>
      </geometry>
    </collision>
    <inertial>
      <origin xyz="0.000002 -0.000643 -0.003700"/>
      <mass value="1.608199"/>
      <inertia ixx="2.289726e-3" ixy="-3.320000e-8" ixz="2.242000e-7" iyy="2.500210e-3" iyz="2.427640e-5" izz="1.961411e-3"/>
    </inertial>
  </link>
  <joint name="left_arm/joint_7" type="revolute">
    <parent link="left_arm/link_6"/>
    <child link="left_arm/link_7"/>
    <origin rpy="1.5707963267948966 0 0" xyz="0 0.0635 0.010"/>
    <axis xyz="0 0 1"/>
    <limit acceleration="52.35987755982988" effort="30" jerk="261.79938779914943" lower="-0.17453292519943295" upper="1.5707963267948966" velocity="4.014257279586958"/>
  </joint>
  <link name="left_arm/link_7">
    <visual>
      <geometry>
        <mesh filename="/home/takuma/code/isaaclab_rl_wearglove/assets/airec/meshes/arm/TRBD-LA-A-001-7/DAE/link7.dae" scale="1.0 1.0 1.0"/>
      </geometry>
      <material name="white"/>
    </visual>
    <collision>
      <geometry>
        <mesh filename="/home/takuma/code/isaaclab_rl_wearglove/assets/airec/meshes/arm/TRBD-LA-A-001-7/STL/link7.stl" scale="1.0 1.0 1.0"/>
      </geometry>
    </collision>
    <inertial>
      <origin xyz="0.000578 0.001148 0.029320"/>
      <mass value="0.363138"/>
      <inertia ixx="2.000245e-4" ixy="2.635000e-7" ixz="4.642300e-6" iyy="2.071647e-4" iyz="7.464500e-6" izz="2.291853e-4"/>
    </inertial>
  </link>
  <joint name="left_arm/joint_tip" type="fixed">
    <parent link="left_arm/link_7"/>
    <child link="left_arm/link_tip"/>
    <origin rpy="3.141592653589793 0 0" xyz="0 0 0"/>
  </joint>
  <link name="left_arm/link_tip"/>
  <joint name="left_arm/joint_load" type="fixed">
    <parent link="left_arm/link_tip"/>
    <child link="left_arm/link_load"/>
    <origin rpy="0 0 0" xyz="0 0 0"/>
  </joint>
  <link name="left_arm/link_load"/>
 
  <!-- =============== Constants =============== -->
  <joint name="right_arm/root" type="fixed">
    <origin rpy="0 0 0" xyz="0 0 0"/>
    <parent link="torso/right_shoulder_link"/>
    <child link="right_arm/link_0"/>
  </joint>
  <link name="right_arm/link_0">
    <inertial>
      <origin xyz="-0.000035 -0.000022 0.001990"/>
      <mass value="1.803167"/>
      <inertia ixx="2.426334e-3" ixy="-4.473000e-7" ixz="-8.480000e-8" iyy="2.426084e-3" iyz="-4.440000e-8" izz="2.142324e-3"/>
    </inertial>
  </link>
  <joint name="right_arm/joint_1" type="revolute">
    <parent link="right_arm/link_0"/>
    <child link="right_arm/link_1"/>
    <origin rpy="0 0 0" xyz="0 0 0.1641"/>
    <axis xyz="0 0 1"/>
    <limit acceleration="27.925268031909273" effort="220" jerk="139.62634015954634" lower="-1.2217304763960306" upper="4.1887902047863905" velocity="2.6179938779914944"/>
  </joint>
  <link name="right_arm/link_1">
    <visual>
      <geometry>
        <mesh filename="/home/takuma/code/isaaclab_rl_wearglove/assets/airec/meshes/arm/TRBD-RA-A-001-7/DAE/link1.dae" scale="1.0 1.0 1.0"/>
      </geometry>
      <material name="white"/>
    </visual>
    <collision>
      <geometry>
        <mesh filename="/home/takuma/code/isaaclab_rl_wearglove/assets/airec/meshes/arm/TRBD-RA-A-001-7/STL/link1.stl" scale="1.0 1.0 1.0"/>
      </geometry>
    </collision>
    <inertial>
      <origin xyz="0.003840 -0.000548 -0.039985"/>
      <mass value="4.396916"/>
      <inertia ixx="1.841398e-2" ixy="2.385544e-4" ixz="-1.283648e-3" iyy="1.950780e-2" iyz="1.539393e-3" izz="9.370438e-3"/>
    </inertial>
  </link>
  <joint name="right_arm/joint_2" type="revolute">
    <parent link="right_arm/link_1"/>
    <child link="right_arm/link_2"/>
    <origin rpy="0 -1.5707963267948966 -1.5707963267948966" xyz="0.010 0 0"/>
    <axis xyz="0 0 1"/>
    <limit acceleration="27.925268031909273" effort="220" jerk="139.62634015954634" lower="-2.1816615649929116" upper="0.3490658503988659" velocity="2.6179938779914944"/>
  </joint>
  <link name="right_arm/link_2">
    <visual>
      <geometry>
        <mesh filename="/home/takuma/code/isaaclab_rl_wearglove/assets/airec/meshes/arm/TRBD-RA-A-001-7/DAE/link2.dae" scale="1.0 1.0 1.0"/>
      </geometry>
      <material name="white"/>
    </visual>
    <collision>
      <geometry>
        <mesh filename="/home/takuma/code/isaaclab_rl_wearglove/assets/airec/meshes/arm/TRBD-RA-A-001-7/STL/link2.stl" scale="1.0 1.0 1.0"/>
      </geometry>
    </collision>
    <inertial>
      <origin xyz="0.005093 0.072288 0.008476"/>
      <mass value="4.970061"/>
      <inertia ixx="4.008293e-2" ixy="-1.371946e-3" ixz="2.173618e-4" iyy="1.337824e-2" iyz="3.067954e-3" izz="3.743154e-2"/>
    </inertial>
  </link>
  <joint name="right_arm/joint_3" type="revolute">
    <parent link="right_arm/link_2"/>
    <child link="right_arm/link_3"/>
    <origin rpy="0 -1.5707963267948966 -1.5707963267948966" xyz="0.010 0.335 0"/>
    <axis xyz="0 0 1"/>
    <limit acceleration="38.39724354387525" effort="110" jerk="191.9862177193762" lower="-2.0943951023931953" upper="2.0943951023931953" velocity="3.3161255787892263"/>
  </joint>
  <link name="right_arm/link_3">
    <visual>
      <geometry>
        <mesh filename="/home/takuma/code/isaaclab_rl_wearglove/assets/airec/meshes/arm/TRBD-RA-A-001-7/DAE/link3.dae" scale="1.0 1.0 1.0"/>
      </geometry>
      <material name="white"/>
    </visual>
    <collision>
      <geometry>
        <mesh filename="/home/takuma/code/isaaclab_rl_wearglove/assets/airec/meshes/arm/TRBD-RA-A-001-7/STL/link3.stl" scale="1.0 1.0 1.0"/>
      </geometry>
    </collision>
    <inertial>
      <origin xyz="0.006101 -0.001974 -0.041100"/>
      <mass value="3.884615"/>
      <inertia ixx="2.115675e-2" ixy="1.199832e-4" ixz="-2.294715e-3" iyy="2.171611e-2" iyz="5.141904e-4" izz="7.974286e-3"/>
    </inertial>
  </link>
  <joint name="right_arm/joint_4" type="revolute">
    <parent link="right_arm/link_3"/>
    <child link="right_arm/link_4"/>
    <origin rpy="-1.5707963267948966 0 0" xyz="0.020 0 0"/>
    <axis xyz="0 0 1"/>
    <limit acceleration="38.39724354387525" effort="110" jerk="191.9862177193762" lower="-0.17453292519943295" upper="2.443460952792061" velocity="3.3161255787892263"/>
  </joint>
  <link name="right_arm/link_4">
    <visual>
      <geometry>
        <mesh filename="/home/takuma/code/isaaclab_rl_wearglove/assets/airec/meshes/arm/TRBD-RA-A-001-7/DAE/link4.dae" scale="1.0 1.0 1.0"/>
      </geometry>
      <material name="white"/>
    </visual>
    <collision>
      <geometry>
        <mesh filename="/home/takuma/code/isaaclab_rl_wearglove/assets/airec/meshes/arm/TRBD-RA-A-001-7/STL/link4.stl" scale="1.0 1.0 1.0"/>
      </geometry>
    </collision>
    <inertial>
      <origin xyz="-0.013158 -0.043830 0.004280"/>
      <mass value="3.170001"/>
      <inertia ixx="1.813721e-2" ixy="-1.679090e-3" ixz="-1.819500e-4" iyy="7.972041e-3" iyz="-8.906634e-4" izz="1.645831e-2"/>
    </inertial>
  </link>
  <joint name="right_arm/joint_5" type="revolute">
    <parent link="right_arm/link_4"/>
    <child link="right_arm/link_5"/>
    <origin rpy="0 1.5707963267948966 -1.5707963267948966" xyz="-0.020 -0.345 0"/>
    <axis xyz="0 0 1"/>
    <limit acceleration="52.35987755982988" effort="50" jerk="261.79938779914943" lower="-2.9670597283903604" upper="2.9670597283903604" velocity="4.014257279586958"/>
  </joint>
  <link name="right_arm/link_5">
    <visual>
      <geometry>
        <mesh filename="/home/takuma/code/isaaclab_rl_wearglove/assets/airec/meshes/arm/TRBD-RA-A-001-7/DAE/link5.dae" scale="1.0 1.0 1.0"/>
      </geometry>
      <material name="white"/>
    </visual>
    <collision>
      <geometry>
        <mesh filename="/home/takuma/code/isaaclab_rl_wearglove/assets/airec/meshes/arm/TRBD-RA-A-001-7/STL/link5.stl" scale="1.0 1.0 1.0"/>
      </geometry>
    </collision>
    <inertial>
      <origin xyz="0.000023 0.020938 -0.116946"/>
      <mass value="2.366366"/>
      <inertia ixx="1.328360e-2" ixy="2.245700e-6" ixz="3.003300e-6" iyy="1.198735e-2" iyz="-3.387750e-3" izz="4.541351e-3"/>
    </inertial>
  </link>
  <joint name="right_arm/joint_6" type="revolute">
    <parent link="right_arm/link_5"/>
    <child link="right_arm/link_6"/>
    <origin rpy="0 -1.5707963267948966 -1.5707963267948966" xyz="0 0 0"/>
    <axis xyz="0 0 1"/>
    <limit acceleration="52.35987755982988" effort="50" jerk="261.79938779914943" lower="-1.5707963267948966" upper="1.5707963267948966" velocity="4.014257279586958"/>
  </joint>
  <link name="right_arm/link_6">
    <visual>
      <geometry>
        <mesh filename="/home/takuma/code/isaaclab_rl_wearglove/assets/airec/meshes/arm/TRBD-RA-A-001-7/DAE/link6.dae" scale="1.0 1.0 1.0"/>
      </geometry>
      <material name="white"/>
    </visual>
    <collision>
      <geometry>
        <mesh filename="/home/takuma/code/isaaclab_rl_wearglove/assets/airec/meshes/arm/TRBD-RA-A-001-7/STL/link6.stl" scale="1.0 1.0 1.0"/>
      </geometry>
    </collision>
    <inertial>
      <origin xyz="0.000002 0.000643 0.003700"/>
      <mass value="1.608199"/>
      <inertia ixx="2.289726e-3" ixy="3.320000e-8" ixz="-2.242000e-7" iyy="2.500210e-3" iyz="2.427640e-5" izz="1.961411e-3"/>
    </inertial>
  </link>
  <joint name="right_arm/joint_7" type="revolute">
    <parent link="right_arm/link_6"/>
    <child link="right_arm/link_7"/>
    <origin rpy="-1.5707963267948966 0 0" xyz="0 0.0635 -0.010"/>
    <axis xyz="0 0 1"/>
    <limit acceleration="52.35987755982988" effort="30" jerk="261.79938779914943" lower="-0.17453292519943295" upper="1.5707963267948966" velocity="4.014257279586958"/>
  </joint>
  <link name="right_arm/link_7">
    <visual>
      <geometry>
        <mesh filename="/home/takuma/code/isaaclab_rl_wearglove/assets/airec/meshes/arm/TRBD-RA-A-001-7/DAE/link7.dae" scale="1.0 1.0 1.0"/>
      </geometry>
      <material name="white"/>
    </visual>
    <collision>
      <geometry>
        <mesh filename="/home/takuma/code/isaaclab_rl_wearglove/assets/airec/meshes/arm/TRBD-RA-A-001-7/STL/link7.stl" scale="1.0 1.0 1.0"/>
      </geometry>
    </collision>
    <inertial>
      <origin xyz="0.000578 -0.001148 -0.029320"/>
      <mass value="0.363138"/>
      <inertia ixx="2.000245e-4" ixy="-2.635000e-7" ixz="-4.642300e-6" iyy="2.071647e-4" iyz="7.464500e-6" izz="2.291853e-4"/>
    </inertial>
  </link>
  <joint name="right_arm/joint_tip" type="fixed">
    <parent link="right_arm/link_7"/>
    <child link="right_arm/link_tip"/>
    <origin rpy="0 0 0" xyz="0 0 0"/>
  </joint>
  <link name="right_arm/link_tip"/>
  <joint name="right_arm/joint_load" type="fixed">
    <parent link="right_arm/link_tip"/>
    <child link="right_arm/link_load"/>
    <origin rpy="0 0 0" xyz="0 0 0"/>
  </joint>
  <link name="right_arm/link_load"/>
  
  <!-- =============== Constants =============== -->
  <joint name="left_hand/base_joint" type="fixed">
    <origin rpy="0 0 0" xyz="0 0 -0.0155"/>
    <parent link="left_arm/link_tip"/>
    <child link="left_hand/base_link"/>
  </joint>
  <link name="left_hand/base_link">
    <visual>
      <geometry>
        <mesh filename="/home/takuma/code/isaaclab_rl_wearglove/assets/airec/meshes/hand/TRBD-LH-A-001-6/DAE/hand_base.dae" scale="1.0 1.0 1.0"/>
      </geometry>
      <material name="white"/>
    </visual>
    <collision>
      <geometry>
        <mesh filename="/home/takuma/code/isaaclab_rl_wearglove/assets/airec/meshes/hand/TRBD-LH-A-001-6/STL/hand_base.stl" scale="1.0 1.0 1.0"/>
      </geometry>
    </collision>
    <inertial>
      <origin xyz="0.08261093 0.005416 -0.0230834"/>
      <mass value="1.624708"/>
      <inertia ixx="3.956243e-3" ixy="-4.300814e-4" ixz="1.621063e-4" iyy="5.450357e-3" iyz="3.624969e-4" izz="7.180913e-3"/>
    </inertial>
  </link>
  <joint name="left_hand/palm_joint" type="fixed">
    <parent link="left_hand/base_link"/>
    <child link="left_hand/palm_link"/>
    <!-- <origin xyz="0.12 0.0 0.0" rpy="0 0 0"/> -->
    <origin rpy="0 0 0" xyz="0.18 0.0 0.0"/>
  </joint>
  <link name="left_hand/palm_link"/>
  <joint name="left_hand_thumb/root" type="fixed">
    <origin rpy="0 0 0" xyz="0.101955 0.040 -0.006"/>
    <parent link="left_hand/base_link"/>
    <child link="left_hand_thumb/link_0"/>
  </joint>
  <link name="left_hand_thumb/link_0">
    <inertial>
      <mass value="1e-5"/>
      <inertia ixx="1e-8" ixy="0" ixz="0" iyy="1e-8" iyz="0" izz="1e-8"/>
    </inertial>
  </link>
  <joint name="left_hand_thumb/joint_1" type="revolute">
    <parent link="left_hand_thumb/link_0"/>
    <child link="left_hand_thumb/link_1"/>
    <origin rpy="0 -1.5707963267948966 3.141592653589793" xyz="0 0 0"/>
    <axis xyz="0 0 1"/>
    <limit acceleration="3.490658503988659" effort="1.5" jerk="10.471975511965978" lower="0.0" upper="1.3264502315156903" velocity="1.3089969389957472"/>
  </joint>
  <link name="left_hand_thumb/link_1">
    <visual>
      <geometry>
        <mesh filename="/home/takuma/code/isaaclab_rl_wearglove/assets/airec/meshes/hand/TRBD-LH-A-001-6/DAE/thumb_link1.dae" scale="1.0 1.0 1.0"/>
      </geometry>
      <material name="white"/>
    </visual>
    <collision>
      <geometry>
        <mesh filename="/home/takuma/code/isaaclab_rl_wearglove/assets/airec/meshes/hand/TRBD-LH-A-001-6/STL/thumb_link1.stl" scale="1.0 1.0 1.0"/>
      </geometry>
    </collision>
    <inertial>
      <origin xyz="0 0 0"/>
      <mass value="0.05"/>
      <inertia ixx="1e-2" ixy="0" ixz="0" iyy="1e-2" iyz="0" izz="1e-2"/>
    </inertial>
  </link>
  <joint name="left_hand_thumb/joint_2" type="revolute">
    <parent link="left_hand_thumb/link_1"/>
    <child link="left_hand_thumb/link_2"/>
    <axis xyz="0 0 1"/>
    <origin rpy="0 -2.356194490192345 0.2542944720155738" xyz="0.005172 -0.008557 0"/>
    <limit acceleration="3.490658503988659" effort="1.5" jerk="10.471975511965978" lower="0.0" upper="0.6108652381980153" velocity="1.3089969389957472"/>
  </joint>
  <link name="left_hand_thumb/link_2">
    <visual>
      <geometry>
        <mesh filename="/home/takuma/code/isaaclab_rl_wearglove/assets/airec/meshes/hand/TRBD-LH-A-001-6/DAE/thumb_link2.dae" scale="1.0 1.0 1.0"/>
      </geometry>
      <material name="white"/>
    </visual>
    <collision>
      <geometry>
        <mesh filename="/home/takuma/code/isaaclab_rl_wearglove/assets/airec/meshes/hand/TRBD-LH-A-001-6/STL/thumb_link2.stl" scale="1.0 1.0 1.0"/>
      </geometry>
    </collision>
    <inertial>
      <origin xyz="0 0 0"/>
      <mass value="0.05"/>
      <inertia ixx="1e-2" ixy="0" ixz="0" iyy="1e-2" iyz="0" izz="1e-2"/>
    </inertial>
  </link>
  <!-- dummy link & joint-->
  <joint name="left_hand_thumb/joint_2_3" type="fixed">
    <parent link="left_hand_thumb/link_2"/>
    <child link="left_hand_thumb/link_2_3"/>
    <origin rpy="0 1.5707963267948966 0" xyz="0 -0.0395 0"/>
  </joint>
  <link name="left_hand_thumb/link_2_3">
    <inertial>
      <mass value="1e-5"/>
      <inertia ixx="1e-8" ixy="0" ixz="0" iyy="1e-8" iyz="0" izz="1e-8"/>
    </inertial>
  </link>
  <joint name="left_hand_thumb/joint_3" type="revolute">
    <parent link="left_hand_thumb/link_2_3"/>
    <child link="left_hand_thumb/link_3"/>
    <origin rpy="0 0 0.06736970912698112 " xyz="0 0 0"/>
    <axis xyz="0 0 1"/>
    <limit acceleration="3.490658503988659" effort="1.5" jerk="10.471975511965978" lower="0.0" upper="0.8726646259971648" velocity="1.3089969389957472"/>
  </joint>
  <link name="left_hand_thumb/link_3">
    <visual>
      <geometry>
        <mesh filename="/home/takuma/code/isaaclab_rl_wearglove/assets/airec/meshes/hand/TRBD-LH-A-001-6/DAE/thumb_link3.dae" scale="1.0 1.0 1.0"/>
      </geometry>
      <material name="white"/>
    </visual>
    <collision>
      <geometry>
        <mesh filename="/home/takuma/code/isaaclab_rl_wearglove/assets/airec/meshes/hand/TRBD-LH-A-001-6/STL/thumb_link3.stl" scale="1.0 1.0 1.0"/>
      </geometry>
    </collision>
    <inertial>
      <origin xyz="0 0 0"/>
      <mass value="0.05"/>
      <inertia ixx="1e-2" ixy="0" ixz="0" iyy="1e-2" iyz="0" izz="1e-2"/>
    </inertial>
  </link>
  <joint name="left_hand_thumb/joint_4" type="revolute">
    <parent link="left_hand_thumb/link_3"/>
    <child link="left_hand_thumb/link_4"/>
    <origin rpy="0 0 0" xyz="-0.002 -0.042 0"/>
    <axis xyz="0 0 1"/>
    <limit acceleration="3.490658503988659" effort="1.5" jerk="10.471975511965978" lower="0.0" upper="0.8726646259971648" velocity="1.3089969389957472"/>
    <mimic joint="left_hand_thumb/joint_3" multiplier="1.0" offset="0.0"/>
  </joint>
  <link name="left_hand_thumb/link_4">
    <visual>
      <geometry>
        <mesh filename="/home/takuma/code/isaaclab_rl_wearglove/assets/airec/meshes/hand/TRBD-LH-A-001-6/DAE/thumb_link4.dae" scale="1.0 1.0 1.0"/>
      </geometry>
      <material name="white"/>
    </visual>
    <collision>
      <geometry>
        <mesh filename="/home/takuma/code/isaaclab_rl_wearglove/assets/airec/meshes/hand/TRBD-LH-A-001-6/STL/thumb_link4.stl" scale="1.0 1.0 1.0"/>
      </geometry>
    </collision>
    <inertial>
      <origin xyz="0 0 0"/>
      <mass value="0.05"/>
      <inertia ixx="1e-2" ixy="0" ixz="0" iyy="1e-2" iyz="0" izz="1e-2"/>
    </inertial>
  </link>
  <joint name="left_hand_thumb/joint_tip" type="fixed">
    <parent link="left_hand_thumb/link_4"/>
    <child link="left_hand_thumb/link_tip"/>
    <origin rpy="0 0 0" xyz="0 0 0"/>
  </joint>
  <link name="left_hand_thumb/link_tip"/>

  
  
  <joint name="left_hand_first_finger/root" type="fixed">
    <origin rpy="0 0 0.13962634015954636" xyz="0.167377 0.047504 0"/>
    <parent link="left_hand/base_link"/>
    <child link="left_hand_first_finger/link_0"/>
  </joint>
  <link name="left_hand_first_finger/link_0">
    <inertial>
      <mass value="1e-5"/>
      <inertia ixx="1e-8" ixy="0" ixz="0" iyy="1e-8" iyz="0" izz="1e-8"/>
    </inertial>
  </link>
  <joint name="left_hand_first_finger/joint_1" type="revolute">
    <parent link="left_hand_first_finger/link_0"/>
    <child link="left_hand_first_finger/link_1"/>
    <origin rpy="0 -1.5707963267948966 1.5707963267948966" xyz="0 0 0"/>
    <axis xyz="0 0 1"/>
    <limit acceleration="3.490658503988659" effort="1.5" jerk="10.471975511965978" lower="0.0" upper="1.5707963267948966" velocity="1.3089969389957472"/>
  </joint>
  <link name="left_hand_first_finger/link_1">
    <visual>
      <geometry>
        <mesh filename="/home/takuma/code/isaaclab_rl_wearglove/assets/airec/meshes/hand/TRBD-LH-A-001-6/DAE/finger_link1.dae" scale="1.0 1.0 1.0"/>
      </geometry>
      <material name="white"/>
    </visual>
    <collision>
      <geometry>
        <mesh filename="/home/takuma/code/isaaclab_rl_wearglove/assets/airec/meshes/hand/TRBD-LH-A-001-6/STL/finger_link1.stl" scale="1.0 1.0 1.0"/>
      </geometry>
    </collision>
    <inertial>
      <origin xyz="0 0 0"/>
      <mass value="0.05"/>
      <inertia ixx="1e-2" ixy="0" ixz="0" iyy="1e-2" iyz="0" izz="1e-2"/>
    </inertial>
  </link>
  <joint name="left_hand_first_finger/joint_2" type="revolute">
    <parent link="left_hand_first_finger/link_1"/>
    <child link="left_hand_first_finger/link_2"/>
    <origin rpy="0 0 0.05951572749300663" xyz="-0.0035 -0.048 0"/>
    <axis xyz="0 0 1"/>
    <limit acceleration="3.490658503988659" effort="1.5" jerk="10.471975511965978" lower="0.0" upper="1.5707963267948966" velocity="1.3089969389957472"/>
    <!-- <mimic joint="left_hand_first_finger/joint_1" multiplier="1.0" offset="0.0"/> -->
  </joint>
  <link name="left_hand_first_finger/link_2">
    <visual>
      <geometry>
        <mesh filename="/home/takuma/code/isaaclab_rl_wearglove/assets/airec/meshes/hand/TRBD-LH-A-001-6/DAE/finger_link2.dae" scale="1.0 1.0 1.0"/>
      </geometry>
      <material name="white"/>
    </visual>
    <collision>
      <geometry>
        <mesh filename="/home/takuma/code/isaaclab_rl_wearglove/assets/airec/meshes/hand/TRBD-LH-A-001-6/STL/finger_link2.stl" scale="1.0 1.0 1.0"/>
      </geometry>
    </collision>
    <inertial>
      <origin xyz="0 0 0"/>
      <mass value="0.05"/>
      <inertia ixx="1e-2" ixy="0" ixz="0" iyy="1e-2" iyz="0" izz="1e-2"/>
    </inertial>
  </link>
  <joint name="left_hand_first_finger/joint_tip" type="fixed">
    <parent link="left_hand_first_finger/link_2"/>
    <child link="left_hand_first_finger/link_tip"/>
    <origin rpy="0 0 0" xyz="0 0 0"/>
  </joint>
  <link name="left_hand_first_finger/link_tip"/>
  
  
  <joint name="left_hand_second_finger/root" type="fixed">
    <origin rpy="0 0 0" xyz="0.180 0.010 0"/>
    <parent link="left_hand/base_link"/>
    <child link="left_hand_second_finger/link_0"/>
  </joint>
  <link name="left_hand_second_finger/link_0">
    <inertial>
      <mass value="1e-5"/>
      <inertia ixx="1e-8" ixy="0" ixz="0" iyy="1e-8" iyz="0" izz="1e-8"/>
    </inertial>
  </link>
  <joint name="left_hand_second_finger/joint_1" type="revolute">
    <parent link="left_hand_second_finger/link_0"/>
    <child link="left_hand_second_finger/link_1"/>
    <origin rpy="0 -1.5707963267948966 1.5707963267948966" xyz="0 0 0"/>
    <axis xyz="0 0 1"/>
    <limit acceleration="3.490658503988659" effort="1.5" jerk="10.471975511965978" lower="0.0" upper="1.5707963267948966" velocity="1.3089969389957472"/>
  </joint>
  <link name="left_hand_second_finger/link_1">
    <visual>
      <geometry>
        <mesh filename="/home/takuma/code/isaaclab_rl_wearglove/assets/airec/meshes/hand/TRBD-LH-A-001-6/DAE/finger_link1.dae" scale="1.0 1.0 1.0"/>
      </geometry>
      <material name="white"/>
    </visual>
    <collision>
      <geometry>
        <mesh filename="/home/takuma/code/isaaclab_rl_wearglove/assets/airec/meshes/hand/TRBD-LH-A-001-6/STL/finger_link1.stl" scale="1.0 1.0 1.0"/>
      </geometry>
    </collision>
    <inertial>
      <origin xyz="0 0 0"/>
      <mass value="0.05"/>
      <inertia ixx="1e-2" ixy="0" ixz="0" iyy="1e-2" iyz="0" izz="1e-2"/>
    </inertial>
  </link>
  <joint name="left_hand_second_finger/joint_2" type="revolute">
    <parent link="left_hand_second_finger/link_1"/>
    <child link="left_hand_second_finger/link_2"/>
    <origin rpy="0 0 0.05951572749300663" xyz="-0.0035 -0.048 0"/>
    <axis xyz="0 0 1"/>
    <limit acceleration="3.490658503988659" effort="1.5" jerk="10.471975511965978" lower="0.0" upper="1.5707963267948966" velocity="1.3089969389957472"/>
    <mimic joint="left_hand_second_finger/joint_1" multiplier="1.0" offset="0.0"/>
  </joint>
  <link name="left_hand_second_finger/link_2">
    <visual>
      <geometry>
        <mesh filename="/home/takuma/code/isaaclab_rl_wearglove/assets/airec/meshes/hand/TRBD-LH-A-001-6/DAE/finger_link2.dae" scale="1.0 1.0 1.0"/>
      </geometry>
      <material name="white"/>
    </visual>
    <collision>
      <geometry>
        <mesh filename="/home/takuma/code/isaaclab_rl_wearglove/assets/airec/meshes/hand/TRBD-LH-A-001-6/STL/finger_link2.stl" scale="1.0 1.0 1.0"/>
      </geometry>
    </collision>
    <inertial>
      <origin xyz="0 0 0"/>
      <mass value="0.05"/>
      <inertia ixx="1e-2" ixy="0" ixz="0" iyy="1e-2" iyz="0" izz="1e-2"/>
    </inertial>
  </link>
  <joint name="left_hand_second_finger/joint_tip" type="fixed">
    <parent link="left_hand_second_finger/link_2"/>
    <child link="left_hand_second_finger/link_tip"/>
    <origin rpy="0 0 0" xyz="0 0 0"/>
  </joint>
  <link name="left_hand_second_finger/link_tip"/>
  
  
  <joint name="left_hand_third_finger/root" type="fixed">
    <origin rpy="0 0 -0.13962634015954636" xyz="0.167377 -0.027504 0"/>
    <parent link="left_hand/base_link"/>
    <child link="left_hand_third_finger/link_0"/>
  </joint>
  <link name="left_hand_third_finger/link_0">
    <inertial>
      <mass value="1e-5"/>
      <inertia ixx="1e-8" ixy="0" ixz="0" iyy="1e-8" iyz="0" izz="1e-8"/>
    </inertial>
  </link>
  <joint name="left_hand_third_finger/joint_1" type="revolute">
    <parent link="left_hand_third_finger/link_0"/>
    <child link="left_hand_third_finger/link_1"/>
    <origin rpy="0 -1.5707963267948966 1.5707963267948966" xyz="0 0 0"/>
    <axis xyz="0 0 1"/>
    <limit acceleration="3.490658503988659" effort="1.5" jerk="10.471975511965978" lower="0.0" upper="1.5707963267948966" velocity="1.3089969389957472"/>
  </joint>
  <link name="left_hand_third_finger/link_1">
    <visual>
      <geometry>
        <mesh filename="/home/takuma/code/isaaclab_rl_wearglove/assets/airec/meshes/hand/TRBD-LH-A-001-6/DAE/finger_link1.dae" scale="1.0 1.0 1.0"/>
      </geometry>
      <material name="white"/>
    </visual>
    <collision>
      <geometry>
        <mesh filename="/home/takuma/code/isaaclab_rl_wearglove/assets/airec/meshes/hand/TRBD-LH-A-001-6/STL/finger_link1.stl" scale="1.0 1.0 1.0"/>
      </geometry>
    </collision>
    <inertial>
      <origin xyz="0 0 0"/>
      <mass value="0.05"/>
      <inertia ixx="1e-2" ixy="0" ixz="0" iyy="1e-2" iyz="0" izz="1e-2"/>
    </inertial>
  </link>
  <joint name="left_hand_third_finger/joint_2" type="revolute">
    <parent link="left_hand_third_finger/link_1"/>
    <child link="left_hand_third_finger/link_2"/>
    <origin rpy="0 0 0.05951572749300663" xyz="-0.0035 -0.048 0"/>
    <axis xyz="0 0 1"/>
    <limit acceleration="3.490658503988659" effort="1.5" jerk="10.471975511965978" lower="0.0" upper="1.5707963267948966" velocity="1.3089969389957472"/>
    <mimic joint="left_hand_third_finger/joint_1" multiplier="1.0" offset="0.0"/>
  </joint>
  <link name="left_hand_third_finger/link_2">
    <visual>
      <geometry>
        <mesh filename="/home/takuma/code/isaaclab_rl_wearglove/assets/airec/meshes/hand/TRBD-LH-A-001-6/DAE/finger_link2.dae" scale="1.0 1.0 1.0"/>
      </geometry>
      <material name="white"/>
    </visual>
    <collision>
      <geometry>
        <mesh filename="/home/takuma/code/isaaclab_rl_wearglove/assets/airec/meshes/hand/TRBD-LH-A-001-6/STL/finger_link2.stl" scale="1.0 1.0 1.0"/>
      </geometry>
    </collision>
    <inertial>
      <origin xyz="0 0 0"/>
      <mass value="0.05"/>
      <inertia ixx="1e-2" ixy="0" ixz="0" iyy="1e-2" iyz="0" izz="1e-2"/>
    </inertial>
  </link>
  <joint name="left_hand_third_finger/joint_tip" type="fixed">
    <parent link="left_hand_third_finger/link_2"/>
    <child link="left_hand_third_finger/link_tip"/>
    <origin rpy="0 0 0" xyz="0 0 0"/>
  </joint>
  <link name="left_hand_third_finger/link_tip"/>
 
  
  <!-- hand_base -->
  <!-- =============== Constants =============== -->
  <joint name="right_hand/base_joint" type="fixed">
    <origin rpy="0 0 0" xyz="0 0 -0.0155"/>
    <parent link="right_arm/link_tip"/>
    <child link="right_hand/base_link"/>
  </joint>
  <link name="right_hand/base_link">
    <visual>
      <geometry>
        <mesh filename="/home/takuma/code/isaaclab_rl_wearglove/assets/airec/meshes/hand/TRBD-RH-A-001-6/DAE/hand_base.dae" scale="1.0 1.0 1.0"/>
      </geometry>
      <material name="white"/>
    </visual>
    <collision>
      <geometry>
        <mesh filename="/home/takuma/code/isaaclab_rl_wearglove/assets/airec/meshes/hand/TRBD-RH-A-001-6/STL/hand_base.stl" scale="1.0 1.0 1.0"/>
      </geometry>
    </collision>
    <inertial>
      <origin xyz="0.08261093 -0.005416 -0.0230834"/>
      <mass value="1.624708"/>
      <inertia ixx="3.956243e-3" ixy="4.300814e-4" ixz="1.621063e-4" iyy="5.450357e-3" iyz="-3.624969e-4" izz="7.180913e-3"/>
    </inertial>
  </link>
  <joint name="right_hand/palm_joint" type="fixed">
    <parent link="right_hand/base_link"/>
    <child link="right_hand/palm_link"/>
    <!-- <origin xyz="0.12 0.0 0.0" rpy="0 0 0"/> -->
    <origin rpy="0 0 0" xyz="0.18 0.0 0.0"/>
  </joint>
  <link name="right_hand/palm_link"/>
  <joint name="right_hand_thumb/root" type="fixed">
    <origin rpy="0 0 0" xyz="0.101955 -0.040 -0.006"/>
    <parent link="right_hand/base_link"/>
    <child link="right_hand_thumb/link_0"/>
  </joint>
  <link name="right_hand_thumb/link_0">
    <inertial>
      <mass value="1e-5"/>
      <inertia ixx="1e-8" ixy="0" ixz="0" iyy="1e-8" iyz="0" izz="1e-8"/>
    </inertial>
  </link>
  <joint name="right_hand_thumb/joint_1" type="revolute">
    <parent link="right_hand_thumb/link_0"/>
    <child link="right_hand_thumb/link_1"/>
    <origin rpy="0 -1.5707963267948966 0" xyz="0 0 0"/>
    <axis xyz="0 0 1"/>
    <limit acceleration="3.490658503988659" effort="1.5" jerk="10.471975511965978" lower="0.0" upper="1.3264502315156903" velocity="1.3089969389957472"/>
  </joint>
  <link name="right_hand_thumb/link_1">
    <visual>
      <geometry>
        <mesh filename="/home/takuma/code/isaaclab_rl_wearglove/assets/airec/meshes/hand/TRBD-RH-A-001-6/DAE/thumb_link1.dae" scale="1.0 1.0 1.0"/>
      </geometry>
      <material name="white"/>
    </visual>
    <collision>
      <geometry>
        <mesh filename="/home/takuma/code/isaaclab_rl_wearglove/assets/airec/meshes/hand/TRBD-RH-A-001-6/STL/thumb_link1.stl" scale="1.0 1.0 1.0"/>
      </geometry>
    </collision>
    <inertial>
      <origin xyz="0 0 0"/>
      <mass value="0.05"/>
      <inertia ixx="1e-2" ixy="0" ixz="0" iyy="1e-2" iyz="0" izz="1e-2"/>
    </inertial>
  </link>
  <joint name="right_hand_thumb/joint_2" type="revolute">
    <parent link="right_hand_thumb/link_1"/>
    <child link="right_hand_thumb/link_2"/>
    <axis xyz="0 0 1"/>
    <origin rpy="0 2.356194490192345 0.2542944720155738" xyz="0.005172 -0.008557 0"/>
    <limit acceleration="3.490658503988659" effort="1.5" jerk="10.471975511965978" lower="0.0" upper="0.6108652381980153" velocity="1.3089969389957472"/>
  </joint>
  <link name="right_hand_thumb/link_2">
    <visual>
      <geometry>
        <mesh filename="/home/takuma/code/isaaclab_rl_wearglove/assets/airec/meshes/hand/TRBD-RH-A-001-6/DAE/thumb_link2.dae" scale="1.0 1.0 1.0"/>
      </geometry>
      <material name="white"/>
    </visual>
    <collision>
      <geometry>
        <mesh filename="/home/takuma/code/isaaclab_rl_wearglove/assets/airec/meshes/hand/TRBD-RH-A-001-6/STL/thumb_link2.stl" scale="1.0 1.0 1.0"/>
      </geometry>
    </collision>
    <inertial>
      <origin xyz="0 0 0"/>
      <mass value="0.05"/>
      <inertia ixx="1e-2" ixy="0" ixz="0" iyy="1e-2" iyz="0" izz="1e-2"/>
    </inertial>
  </link>
  <!-- dummy link & joint-->
  <joint name="right_hand_thumb/joint_2_3" type="fixed">
    <parent link="right_hand_thumb/link_2"/>
    <child link="right_hand_thumb/link_2_3"/>
    <origin rpy="0 -1.5707963267948966 0" xyz="0 -0.0395 0"/>
  </joint>
  <link name="right_hand_thumb/link_2_3">
    <inertial>
      <mass value="1e-5"/>
      <inertia ixx="1e-8" ixy="0" ixz="0" iyy="1e-8" iyz="0" izz="1e-8"/>
    </inertial>
  </link>
  <joint name="right_hand_thumb/joint_3" type="revolute">
    <parent link="right_hand_thumb/link_2_3"/>
    <child link="right_hand_thumb/link_3"/>
    <origin rpy="0 0 0.06736970912698112 " xyz="0 0 0"/>
    <axis xyz="0 0 1"/>
    <limit acceleration="3.490658503988659" effort="1.5" jerk="10.471975511965978" lower="0.0" upper="0.8726646259971648" velocity="1.3089969389957472"/>
  </joint>
  <link name="right_hand_thumb/link_3">
    <visual>
      <geometry>
        <mesh filename="/home/takuma/code/isaaclab_rl_wearglove/assets/airec/meshes/hand/TRBD-RH-A-001-6/DAE/thumb_link3.dae" scale="1.0 1.0 1.0"/>
      </geometry>
      <material name="white"/>
    </visual>
    <collision>
      <geometry>
        <mesh filename="/home/takuma/code/isaaclab_rl_wearglove/assets/airec/meshes/hand/TRBD-RH-A-001-6/STL/thumb_link3.stl" scale="1.0 1.0 1.0"/>
      </geometry>
    </collision>
    <inertial>
      <origin xyz="0 0 0"/>
      <mass value="0.05"/>
      <inertia ixx="1e-2" ixy="0" ixz="0" iyy="1e-2" iyz="0" izz="1e-2"/>
    </inertial>
  </link>
  <joint name="right_hand_thumb/joint_4" type="revolute">
    <parent link="right_hand_thumb/link_3"/>
    <child link="right_hand_thumb/link_4"/>
    <origin rpy="0 0 0" xyz="-0.002 -0.042 0"/>
    <axis xyz="0 0 1"/>
    <limit acceleration="3.490658503988659" effort="1.5" jerk="10.471975511965978" lower="0.0" upper="0.8726646259971648" velocity="1.3089969389957472"/>
    <mimic joint="right_hand_thumb/joint_3" multiplier="1.0" offset="0.0"/>
  </joint>
  <link name="right_hand_thumb/link_4">
    <visual>
      <geometry>
        <mesh filename="/home/takuma/code/isaaclab_rl_wearglove/assets/airec/meshes/hand/TRBD-RH-A-001-6/DAE/thumb_link4.dae" scale="1.0 1.0 1.0"/>
      </geometry>
      <material name="white"/>
    </visual>
    <collision>
      <geometry>
        <mesh filename="/home/takuma/code/isaaclab_rl_wearglove/assets/airec/meshes/hand/TRBD-RH-A-001-6/STL/thumb_link4.stl" scale="1.0 1.0 1.0"/>
      </geometry>
    </collision>
    <inertial>
      <origin xyz="0 0 0"/>
      <mass value="0.05"/>
      <inertia ixx="1e-2" ixy="0" ixz="0" iyy="1e-2" iyz="0" izz="1e-2"/>
    </inertial>
  </link>
  <joint name="right_hand_thumb/joint_tip" type="fixed">
    <parent link="right_hand_thumb/link_4"/>
    <child link="right_hand_thumb/link_tip"/>
    <origin rpy="0 0 0" xyz="0 0 0"/>
  </joint>
  <link name="right_hand_thumb/link_tip"/>

  
  <joint name="right_hand_first_finger/root" type="fixed">
    <origin rpy="0 0 -0.13962634015954636" xyz="0.167377 -0.047504 0"/>
    <parent link="right_hand/base_link"/>
    <child link="right_hand_first_finger/link_0"/>
  </joint>
  <link name="right_hand_first_finger/link_0">
    <inertial>
      <mass value="1e-5"/>
      <inertia ixx="1e-8" ixy="0" ixz="0" iyy="1e-8" iyz="0" izz="1e-8"/>
    </inertial>
  </link>
  <joint name="right_hand_first_finger/joint_1" type="revolute">
    <parent link="right_hand_first_finger/link_0"/>
    <child link="right_hand_first_finger/link_1"/>
    <origin rpy="0 -1.5707963267948966 1.5707963267948966" xyz="0 0 0"/>
    <axis xyz="0 0 1"/>
    <limit acceleration="3.490658503988659" effort="1.5" jerk="10.471975511965978" lower="0.0" upper="1.5707963267948966" velocity="1.3089969389957472"/>
  </joint>
  <link name="right_hand_first_finger/link_1">
    <visual>
      <geometry>
        <mesh filename="/home/takuma/code/isaaclab_rl_wearglove/assets/airec/meshes/hand/TRBD-RH-A-001-6/DAE/finger_link1.dae" scale="1.0 1.0 1.0"/>
      </geometry>
      <material name="white"/>
    </visual>
    <collision>
      <geometry>
        <mesh filename="/home/takuma/code/isaaclab_rl_wearglove/assets/airec/meshes/hand/TRBD-RH-A-001-6/STL/finger_link1.stl" scale="1.0 1.0 1.0"/>
      </geometry>
    </collision>
    <inertial>
      <origin xyz="0 0 0"/>
      <mass value="0.05"/>
      <inertia ixx="1e-2" ixy="0" ixz="0" iyy="1e-2" iyz="0" izz="1e-2"/>
    </inertial>
  </link>
  <joint name="right_hand_first_finger/joint_2" type="revolute">
    <parent link="right_hand_first_finger/link_1"/>
    <child link="right_hand_first_finger/link_2"/>
    <origin rpy="0 0 0.05951572749300663" xyz="-0.0035 -0.048 0"/>
    <axis xyz="0 0 1"/>
    <limit acceleration="3.490658503988659" effort="1.5" jerk="10.471975511965978" lower="0.0" upper="1.5707963267948966" velocity="1.3089969389957472"/>
    <!-- <mimic joint="right_hand_first_finger/joint_1" multiplier="1.0" offset="0.0"/> --> --> --> -->
  </joint>
  <link name="right_hand_first_finger/link_2">
    <visual>
      <geometry>
        <mesh filename="/home/takuma/code/isaaclab_rl_wearglove/assets/airec/meshes/hand/TRBD-RH-A-001-6/DAE/finger_link2.dae" scale="1.0 1.0 1.0"/>
      </geometry>
      <material name="white"/>
    </visual>
    <collision>
      <geometry>
        <mesh filename="/home/takuma/code/isaaclab_rl_wearglove/assets/airec/meshes/hand/TRBD-RH-A-001-6/STL/finger_link2.stl" scale="1.0 1.0 1.0"/>
      </geometry>
    </collision>
    <inertial>
      <origin xyz="0 0 0"/>
      <mass value="0.05"/>
      <inertia ixx="1e-2" ixy="0" ixz="0" iyy="1e-2" iyz="0" izz="1e-2"/>
    </inertial>
  </link>
  <joint name="right_hand_first_finger/joint_tip" type="fixed">
    <parent link="right_hand_first_finger/link_2"/>
    <child link="right_hand_first_finger/link_tip"/>
    <origin rpy="0 0 0" xyz="0 0 0"/>
  </joint>
  <link name="right_hand_first_finger/link_tip"/>

  
  <joint name="right_hand_second_finger/root" type="fixed">
    <origin rpy="0 0 0" xyz="0.180 -0.010 0"/>
    <parent link="right_hand/base_link"/>
    <child link="right_hand_second_finger/link_0"/>
  </joint>
  <link name="right_hand_second_finger/link_0">
    <inertial>
      <mass value="1e-5"/>
      <inertia ixx="1e-8" ixy="0" ixz="0" iyy="1e-8" iyz="0" izz="1e-8"/>
    </inertial>
  </link>
  <joint name="right_hand_second_finger/joint_1" type="revolute">
    <parent link="right_hand_second_finger/link_0"/>
    <child link="right_hand_second_finger/link_1"/>
    <origin rpy="0 -1.5707963267948966 1.5707963267948966" xyz="0 0 0"/>
    <axis xyz="0 0 1"/>
    <limit acceleration="3.490658503988659" effort="1.5" jerk="10.471975511965978" lower="0.0" upper="1.5707963267948966" velocity="1.3089969389957472"/>
  </joint>
  <link name="right_hand_second_finger/link_1">
    <visual>
      <geometry>
        <mesh filename="/home/takuma/code/isaaclab_rl_wearglove/assets/airec/meshes/hand/TRBD-RH-A-001-6/DAE/finger_link1.dae" scale="1.0 1.0 1.0"/>
      </geometry>
      <material name="white"/>
    </visual>
    <collision>
      <geometry>
        <mesh filename="/home/takuma/code/isaaclab_rl_wearglove/assets/airec/meshes/hand/TRBD-RH-A-001-6/STL/finger_link1.stl" scale="1.0 1.0 1.0"/>
      </geometry>
    </collision>
    <inertial>
      <origin xyz="0 0 0"/>
      <mass value="0.05"/>
      <inertia ixx="1e-2" ixy="0" ixz="0" iyy="1e-2" iyz="0" izz="1e-2"/>
    </inertial>
  </link>
  <joint name="right_hand_second_finger/joint_2" type="revolute">
    <parent link="right_hand_second_finger/link_1"/>
    <child link="right_hand_second_finger/link_2"/>
    <origin rpy="0 0 0.05951572749300663" xyz="-0.0035 -0.048 0"/>
    <axis xyz="0 0 1"/>
    <limit acceleration="3.490658503988659" effort="1.5" jerk="10.471975511965978" lower="0.0" upper="1.5707963267948966" velocity="1.3089969389957472"/>
    <mimic joint="right_hand_second_finger/joint_1" multiplier="1.0" offset="0.0"/>
  </joint>
  <link name="right_hand_second_finger/link_2">
    <visual>
      <geometry>
        <mesh filename="/home/takuma/code/isaaclab_rl_wearglove/assets/airec/meshes/hand/TRBD-RH-A-001-6/DAE/finger_link2.dae" scale="1.0 1.0 1.0"/>
      </geometry>
      <material name="white"/>
    </visual>
    <collision>
      <geometry>
        <mesh filename="/home/takuma/code/isaaclab_rl_wearglove/assets/airec/meshes/hand/TRBD-RH-A-001-6/STL/finger_link2.stl" scale="1.0 1.0 1.0"/>
      </geometry>
    </collision>
    <inertial>
      <origin xyz="0 0 0"/>
      <mass value="0.05"/>
      <inertia ixx="1e-2" ixy="0" ixz="0" iyy="1e-2" iyz="0" izz="1e-2"/>
    </inertial>
  </link>
  <joint name="right_hand_second_finger/joint_tip" type="fixed">
    <parent link="right_hand_second_finger/link_2"/>
    <child link="right_hand_second_finger/link_tip"/>
    <origin rpy="0 0 0" xyz="0 0 0"/>
  </joint>
  <link name="right_hand_second_finger/link_tip"/>

  
  <!-- Joint1 -->
  
  <joint name="right_hand_third_finger/root" type="fixed">
    <origin rpy="0 0 0.13962634015954636" xyz="0.167377 0.027504 0"/>
    <parent link="right_hand/base_link"/>
    <child link="right_hand_third_finger/link_0"/>
  </joint>
  <link name="right_hand_third_finger/link_0">
    <inertial>
      <mass value="1e-5"/>
      <inertia ixx="1e-8" ixy="0" ixz="0" iyy="1e-8" iyz="0" izz="1e-8"/>
    </inertial>
  </link>
  <joint name="right_hand_third_finger/joint_1" type="revolute">
    <parent link="right_hand_third_finger/link_0"/>
    <child link="right_hand_third_finger/link_1"/>
    <origin rpy="0 -1.5707963267948966 1.5707963267948966" xyz="0 0 0"/>
    <axis xyz="0 0 1"/>
    <limit acceleration="3.490658503988659" effort="1.5" jerk="10.471975511965978" lower="0.0" upper="1.5707963267948966" velocity="1.3089969389957472"/>
  </joint>
  <link name="right_hand_third_finger/link_1">
    <visual>
      <geometry>
        <mesh filename="/home/takuma/code/isaaclab_rl_wearglove/assets/airec/meshes/hand/TRBD-RH-A-001-6/DAE/finger_link1.dae" scale="1.0 1.0 1.0"/>
      </geometry>
      <material name="white"/>
    </visual>
    <collision>
      <geometry>
        <mesh filename="/home/takuma/code/isaaclab_rl_wearglove/assets/airec/meshes/hand/TRBD-RH-A-001-6/STL/finger_link1.stl" scale="1.0 1.0 1.0"/>
      </geometry>
    </collision>
    <inertial>
      <origin xyz="0 0 0"/>
      <mass value="0.05"/>
      <inertia ixx="1e-2" ixy="0" ixz="0" iyy="1e-2" iyz="0" izz="1e-2"/>
    </inertial>
  </link>
  <joint name="right_hand_third_finger/joint_2" type="revolute">
    <parent link="right_hand_third_finger/link_1"/>
    <child link="right_hand_third_finger/link_2"/>
    <origin rpy="0 0 0.05951572749300663" xyz="-0.0035 -0.048 0"/>
    <axis xyz="0 0 1"/>
    <limit acceleration="3.490658503988659" effort="1.5" jerk="10.471975511965978" lower="0.0" upper="1.5707963267948966" velocity="1.3089969389957472"/>
    <mimic joint="right_hand_third_finger/joint_1" multiplier="1.0" offset="0.0"/>
  </joint>
  <link name="right_hand_third_finger/link_2">
    <visual>
      <geometry>
        <mesh filename="/home/takuma/code/isaaclab_rl_wearglove/assets/airec/meshes/hand/TRBD-RH-A-001-6/DAE/finger_link2.dae" scale="1.0 1.0 1.0"/>
      </geometry>
      <material name="white"/>
    </visual>
    <collision>
      <geometry>
        <mesh filename="/home/takuma/code/isaaclab_rl_wearglove/assets/airec/meshes/hand/TRBD-RH-A-001-6/STL/finger_link2.stl" scale="1.0 1.0 1.0"/>
      </geometry>
    </collision>
    <inertial>
      <origin xyz="0 0 0"/>
      <mass value="0.05"/>
      <inertia ixx="1e-2" ixy="0" ixz="0" iyy="1e-2" iyz="0" izz="1e-2"/>
    </inertial>
  </link>
  <joint name="right_hand_third_finger/joint_tip" type="fixed">
    <parent link="right_hand_third_finger/link_2"/>
    <child link="right_hand_third_finger/link_tip"/>
    <origin rpy="0 0 0" xyz="0 0 0"/>
  </joint>
  <link name="right_hand_third_finger/link_tip"/>

  
</robot>
